Workbook

Sheet PC
B1: 관리번호 | C1: PC구분 | D1: 장비상태 | E1: 관리유형 | F1: 모델명 | G1: 제조회사 | H1: 관리실 | I1: IP | J1: 기타 | K1: 불용처분 시기 | L1: 구입일자 | M1: 구입금액 | N1: 구매구분 | O1: 관리자명 | P1: 관리번호 | Q1: 운영체제 | R1: CPU | S1: 주메모리 | T1: HDD | V1: CD-ROM
A2: 김종익 | B2: =L2&"-"&TEXT(P2,"0000") -> 20250708-0803 | C2: 데스크톱 | D2: 활용중 | E2: 직원용 | F2: DS361A-245430 | G2: 대우루컴즈 | H2: =IFERROR(VLOOKUP(O2,'정보화기기 명부'!A$2:B$187,2,FALSE),"") -> 시설관리실 | I2: =IFERROR(VLOOKUP(A2,'교직원용 IP'!$C$2:$H$230,6,FALSE),"") -> 10.51.90.80 | L2: 20250708 | M2: 665975 | N2: 자체구매 | O2: 김종익 | P2: 803 | Q2: WINDOW 11 | R2: Intel Core i5 12400(2.5GHz) | T2: 500GB | V2: DVD_MULTI | W2: LED_24
A3: =O3 -> 성윤정 | B3: =L3&"-"&TEXT(P3,"0000") -> 20250708-0805 | C3: 데스크톱 | D3: 활용중 | E3: 직원용 | F3: DS361A-245430 | G3: 대우루컴즈 | H3: =IFERROR(VLOOKUP(O3,'정보화기기 명부'!A$2:B$187,2,FALSE),"") -> 교육행정실 | I3: =IFERROR(VLOOKUP(A3,'교직원용 IP'!$C$2:$H$230,6,FALSE),"") -> 10.51.90.77 | L3: 20250708 | M3: 665975 | N3: 자체구매 | O3: 성윤정 | P3: 805 | Q3: WINDOW 11 | R3: Intel Core i5 12400(2.5GHz) | T3: 500GB | V3: DVD_MULTI | W3: LED_24
A4: =O4 -> 고가영1 | B4: =L4&"-"&TEXT(P4,"0000") -> 20250708-0808 | C4: 데스크톱 | D4: 활용중 | E4: 교원용 | F4: DS361A-245430 | G4: 대우루컴즈 | H4: =IFERROR(VLOOKUP(O4,'정보화기기 명부'!A$2:B$187,2,FALSE),"") | I4: =IFERROR(VLOOKUP(A4,'교직원용 IP'!$C$2:$H$230,6,FALSE),"") -> 10.51.90.127 | L4: 20250708 | M4: 665975 | N4: 자체구매 | O4: 고가영1 | P4: 808 | Q4: WINDOW 11 | R4: Intel Core i5 12400(2.5GHz) | T4: 500GB | V4: DVD_MULTI | W4: LED_24
A5: =O5 -> 한수진 | B5: =L5&"-"&TEXT(P5,"0000") -> 20250708-0853 | C5: 데스크톱 | D5: 활용중 | E5: 교원용 | F5: DS361A-245430 | G5: 대우루컴즈 | H5: =IFERROR(VLOOKUP(O5,'정보화기기 명부'!A$2:B$187,2,FALSE),"") -> Wee클래스 | I5: =IFERROR(VLOOKUP(O5,'교직원용 IP'!$C$2:$H$230,6,FALSE),"") -> 10.51.90.117 | L5: 20250708 | M5: 897100 | N5: 일괄구매 | O5: 한수진 | P5: 853 | Q5: WINDOW 11 | R5: Intel Core i5 12400(2.5GHz) | T5: 1000GB | V5: 없음
A6: 급식실 | F6: DT281-GA51-012, Intel Core i5 12500(3GHz) | G6: 삼보 | H6: 급식실 | L6: 20231227 | M6: 1036660 | N6: 자체구매 | O6: 급식실
A7: =O7 -> 임향민 | B7: =L7&"-"&TEXT(P7,"0000") -> 20231219-0904 | C7: 데스크톱 | D7: 활용중 | E7: 직원용 | F7: DR281-GS51-012 intel core i5 | G7: 삼보 | H7: 교육행정실 | I7: =IFERROR(VLOOKUP(O7,'교직원용 IP'!$C$2:$H$230,6,FALSE),"") -> 10.51.90.74 | L7: 20231219 | M7: 1036660 | N7: 자체구매 | O7: 임향민 | P7: 904
A8: =O8 -> 황경환 | B8: =L8&"-"&TEXT(P8,"0000") -> 20230721-0903 | C8: 데스크톱 | D8: 활용중 | E8: 직원용 | F8: DG481-GA51-011, Intel Core i5 12500(3GHz) | G8: 삼보 | H8: 2층 교무실 | I8: =IFERROR(VLOOKUP(O8,'교직원용 IP'!$C$2:$H$230,6,FALSE),"") -> 10.51.90.72 | L8: 20230721 | M8: 1028520 | N8: 자체구매 | O8: 황경환 | P8: 903
A9: =O9 -> 고진아 | B9: 20230315-0919 | C9: 노트북 | D9: 활용중 | E9: 교원용 | F9: NT550XED-KG03G | G9: 삼성 | H9: =IFERROR(VLOOKUP(O9,'정보화기기 명부'!A$2:B$187,2,FALSE),"") -> 혁신교육부 | I9: =IFERROR(VLOOKUP(A9,'교직원용 IP'!$C$2:$H$230,6,FALSE),"") -> 10.51.90.83 | L9: 20230315 | M9: 1028000 | N9: 자체구매 | O9: 고진아 | P9: 919 | Q9: WINDOW 11 | R9: Intel Core i5 1135G7 | S9: 8GB | T9: 512GB
A10: =O10 -> 김두순 | B10: 20230315-0920 | C10: 노트북 | D10: 활용중 | E10: 교원용 | F10: NT550XED-KG03G | G10: 삼성 | H10: =IFERROR(VLOOKUP(O10,'정보화기기 명부'!A$2:B$187,2,FALSE),"") -> 수리과학부 | I10: =IFERROR(VLOOKUP(A10,'교직원용 IP'!$C$2:$H$230,6,FALSE),"") -> 10.51.90.84 | L10: 20230315 | M10: 1028000 | N10: 자체구매 | O10: 김두순 | P10: 920 | Q10: WINDOW 11 | R10: Intel Core i5 1135G7 | S10: 8GB | T10: 512GB
A11: =O11 -> 윤샤롬 | B11: 20230315-0921 | C11: 노트북 | D11: 활용중 | E11: 교원용 | F11: NT550XED-KG03G | G11: 삼성 | H11: =IFERROR(VLOOKUP(O11,'정보화기기 명부'!A$2:B$187,2,FALSE),"") -> 3학년부 | I11: =IFERROR(VLOOKUP(A11,'교직원용 IP'!$C$2:$H$230,6,FALSE),"") -> 10.51.90.101 | L11: 20230315 | M11: 1028000 | N11: 자체구매 | O11: 윤샤롬 | P11: 921 | Q11: WINDOW 11 | R11: Intel Core i5 1135G7 | S11: 8GB | T11: 512GB
A12: =O12 -> 교장선 노트북 | B12: =L12&"-"&TEXT(P12,"0000") -> 20220905-0915 | C12: 노트북 | D12: 활용중 | E12: 교원용 | F12: NT550XDA-KG03G | G12: 삼성 | H12: =IFERROR(VLOOKUP(O12,'정보화기기 명부'!A$2:B$187,2,FALSE),"") -> 교장실 | I12: =IFERROR(VLOOKUP(O12,'교직원용 IP'!$C$2:$H$230,6,FALSE),"") -> 10.51.90.144 | L12: 20220905 | M12: 1256750 | N12: 자체구매 | O12: 교장선 노트북 | P12: 915 | Q12: WINDOW 11 | R12: Intel Core i5 1135G7 | S12: 8GB | T12: 512GB | V12: 없음
A13: =O13 -> 민별 | B13: =L13&"-"&TEXT(P13,"0000") -> 20220829-0905 | C13: 노트북 | D13: 활용중 | E13: 교원용 | F13: N5800-G050-OU02 | G13: 삼보 | H13: =IFERROR(VLOOKUP(O13,'정보화기기 명부'!A$2:B$187,2,FALSE),"") -> 3학년부 | I13: =IFERROR(VLOOKUP(O13,'교직원용 IP'!$C$2:$H$230,6,FALSE),"") -> 10.51.90.132 | L13: 20220829 | M13: 896800 | N13: 자체구매 | O13: 민별 | P13: 905 | Q13: WINDOW 11 | R13: Intel Core i5-10210U | S13: 8GB | T13: 256GB SSD + 1GB HDD
A14: =O14 -> 임우혁 | B14: =L14&"-"&TEXT(P14,"0000") -> 20220829-0906 | C14: 노트북 | D14: 활용중 | E14: 교원용 | F14: N5800-G050-OU02 | G14: 삼보 | H14: =IFERROR(VLOOKUP(O14,'정보화기기 명부'!A$2:B$187,2,FALSE),"") -> 교육과정부 | I14: =IFERROR(VLOOKUP(O14,'교직원용 IP'!$C$2:$H$230,6,FALSE),"") -> 10.51.90.131 | L14: 20220829 | M14: 896800 | N14: 자체구매 | O14: 임우혁 | P14: 906 | Q14: WINDOW 11 | R14: Intel Core i5-10210U | S14: 8GB | T14: 256GB SSD + 1GB HDD
A15: =O15 -> 윤선영 | B15: =L15&"-"&TEXT(P15,"0000") -> 20220829-0907 | C15: 노트북 | D15: 활용중 | E15: 교원용 | F15: N5800-G050-OU02 | G15: 삼보 | H15: =IFERROR(VLOOKUP(O15,'정보화기기 명부'!A$2:B$187,2,FALSE),"") -> 1학년부 | I15: =IFERROR(VLOOKUP(O15,'교직원용 IP'!$C$2:$H$230,6,FALSE),"") -> 10.51.90.81 | L15: 20220829 | M15: 896800 | N15: 자체구매 | O15: 윤선영 | P15: 907 | Q15: WINDOW 11 | R15: Intel Core i5-10210U | S15: 8GB | T15: 256GB SSD + 1GB HDD
A16: =O16 -> 허정화 | B16: =L16&"-"&TEXT(P16,"0000") -> 20220829-0908 | C16: 노트북 | D16: 활용중 | E16: 교원용 | F16: N5800-G050-OU02 | G16: 삼보 | H16: =IFERROR(VLOOKUP(O16,'정보화기기 명부'!A$2:B$187,2,FALSE),"") -> 특수교육부 | I16: =IFERROR(VLOOKUP(O16,'교직원용 IP'!$C$2:$H$230,6,FALSE),"") -> 10.51.90.124 | L16: 20220829 | M16: 896800 | N16: 자체구매 | O16: 허정화 | P16: 908 | Q16: WINDOW 11 | R16: Intel Core i5-10210U | S16: 8GB | T16: 256GB SSD + 1GB HDD
A17: =O17 -> 김용숙 | B17: =L17&"-"&TEXT(P17,"0000") -> 20220829-0909 | C17: 노트북 | D17: 활용중 | E17: 교원용 | F17: N5800-G050-OU02 | G17: 삼보 | H17: =IFERROR(VLOOKUP(O17,'정보화기기 명부'!A$2:B$187,2,FALSE),"") -> 수리과학부 | I17: =IFERROR(VLOOKUP(O17,'교직원용 IP'!$C$2:$H$230,6,FALSE),"") -> 10.51.90.126 | L17: 20220829 | M17: 896800 | N17: 자체구매 | O17: 김용숙 | P17: 909 | Q17: WINDOW 11 | R17: Intel Core i5-10210U | S17: 8GB | T17: 256GB SSD + 1GB HDD
A18: =O18 -> 신진태 | B18: =L18&"-"&TEXT(P18,"0000") -> 20220829-0910 | C18: 노트북 | D18: 활용중 | E18: 교원용 | F18: N5800-G050-OU02 | G18: 삼보 | H18: =IFERROR(VLOOKUP(O18,'정보화기기 명부'!A$2:B$187,2,FALSE),"") -> 특수교육부 | I18: =IFERROR(VLOOKUP(O18,'교직원용 IP'!$C$2:$H$230,6,FALSE),"") -> 10.51.90.123 | L18: 20220829 | M18: 896800 | N18: 자체구매 | O18: 신진태 | P18: 910 | Q18: WINDOW 11 | R18: Intel Core i5-10210U | S18: 8GB | T18: 256GB SSD + 1GB HDD
A19: =O19 -> 김태형 | B19: =L19&"-"&TEXT(P19,"0000") -> 20220829-0911 | C19: 노트북 | D19: 활용중 | E19: 교원용 | F19: N5800-G050-OU02 | G19: 삼보 | H19: =IFERROR(VLOOKUP(O19,'정보화기기 명부'!A$2:B$187,2,FALSE),"") -> 학생인권안전부 | I19: =IFERROR(VLOOKUP(O19,'교직원용 IP'!$C$2:$H$230,6,FALSE),"") -> 10.51.90.136 | L19: 20220829 | M19: 896800 | N19: 자체구매 | O19: 김태형 | P19: 911 | Q19: WINDOW 11 | R19: Intel Core i5-10210U | S19: 8GB | T19: 256GB SSD + 1GB HDD
A20: =O20 -> 임숙진 | B20: =L20&"-"&TEXT(P20,"0000") -> 20220829-0912 | C20: 노트북 | D20: 활용중 | E20: 교원용 | F20: N5800-G050-OU02 | G20: 삼보 | H20: =IFERROR(VLOOKUP(O20,'정보화기기 명부'!A$2:B$187,2,FALSE),"") -> 혁신교육부 | I20: =IFERROR(VLOOKUP(O20,'교직원용 IP'!$C$2:$H$230,6,FALSE),"") -> 10.51.90.102 | L20: 20220829 | M20: 896800 | N20: 자체구매 | O20: 임숙진 | P20: 912 | Q20: WINDOW 11 | R20: Intel Core i5-10210U | S20: 8GB | T20: 256GB SSD + 1GB HDD
A21: =O21 -> 맹수용 | B21: =L21&"-"&TEXT(P21,"0000") -> 20220829-0913 | C21: 노트북 | D21: 활용중 | E21: 교원용 | F21: N5800-G050-OU02 | G21: 삼보 | H21: =IFERROR(VLOOKUP(O21,'정보화기기 명부'!A$2:B$187,2,FALSE),"") -> 인문사회부 | I21: =IFERROR(VLOOKUP(O21,'교직원용 IP'!$C$2:$H$230,6,FALSE),"") -> 10.51.90.121 | L21: 20220829 | M21: 896800 | N21: 자체구매 | O21: 맹수용 | P21: 913 | Q21: WINDOW 11 | R21: Intel Core i5-10210U | S21: 8GB | T21: 256GB SSD + 1GB HDD
A22: =O22 -> 정현숙 | B22: =L22&"-"&TEXT(P22,"0000") -> 20220829-0914 | C22: 노트북 | D22: 활용중 | E22: 교원용 | F22: N5800-G050-OU02 | G22: 삼보 | H22: =IFERROR(VLOOKUP(O22,'정보화기기 명부'!A$2:B$187,2,FALSE),"") -> 1학년부 | I22: =IFERROR(VLOOKUP(O22,'교직원용 IP'!$C$2:$H$230,6,FALSE),"") -> 10.51.90.142 | L22: 20220829 | M22: 896800 | N22: 자체구매 | O22: 정현숙 | P22: 914 | Q22: WINDOW 11 | R22: Intel Core i5-10210U | S22: 8GB | T22: 256GB SSD + 1GB HDD
A23: =O23 -> 유희정 | B23: =L23&"-"&TEXT(P23,"0000") -> 20220308-0903 | C23: 노트북 | D23: 활용중 | E23: 교원용 | F23: NT550XDA-KG01G | G23: 삼성 | H23: =IFERROR(VLOOKUP(O23,'정보화기기 명부'!A$2:B$187,2,FALSE),"") -> 정보교육부 | I23: =IFERROR(VLOOKUP(O23,'교직원용 IP'!$C$2:$H$230,6,FALSE),"") -> 10.51.90.107 | L23: 20220308 | M23: 1160000 | N23: 자체구매 | O23: 유희정 | P23: 903 | Q23: WINDOW 10 | R23: i5-1135G7(2.40Ghz) | S23: 8GB | T23: 512GB
A24: =O24 -> 이수경 | B24: =L24&"-"&TEXT(P24,"0000") -> 20220308-0904 | C24: 노트북 | D24: 활용중 | E24: 교원용 | F24: NT550XDA-KG01G | G24: 삼성 | H24: =IFERROR(VLOOKUP(O24,'정보화기기 명부'!A$2:B$187,2,FALSE),"") -> 3학년부 | I24: =IFERROR(VLOOKUP(O24,'교직원용 IP'!$C$2:$H$230,6,FALSE),"") -> 10.51.90.133 | L24: 20220308 | M24: 1160000 | N24: 자체구매 | O24: 이수경 | P24: 904 | Q24: WINDOW 10 | R24: i5-1135G7(2.40Ghz) | S24: 8GB | T24: 512GB
A25: 백양현 | B25: =L25&"-"&TEXT(P25,"0000") -> 20220117-0902 | C25: 데스크톱 | D25: 활용중 | E25: 직원용 | F25: DG375-GA31-0BPS | G25: 삼보 | H25: =IFERROR(VLOOKUP(O25,'정보화기기 명부'!A$2:B$187,2,FALSE),"") | I25: =IFERROR(VLOOKUP(O25,'교직원용 IP'!$C$2:$H$230,6,FALSE),"") | L25: 20220117 | M25: 587000 | N25: 자체구매 | O25: 황성임 | P25: 902 | Q25: WINDOW 10
A26: =O26 -> 김이조 | B26: =L26&"-"&TEXT(P26,"0000") -> 20220117-0901 | C26: 데스크톱 | D26: 활용중 | E26: 직원용 | F26: DG375-GA31-0BPS | G26: 삼보 | H26: =IFERROR(VLOOKUP(O26,'정보화기기 명부'!A$2:B$187,2,FALSE),"") -> 교육행정실 | I26: =IFERROR(VLOOKUP(O26,'교직원용 IP'!$C$2:$H$230,6,FALSE),"") -> 10.51.90.75 | L26: 20220117 | M26: 587000 | N26: 자체구매 | O26: 김이조 | P26: 901 | Q26: WINDOW 10
A27: =O27 -> 정보과학실 학생용 8 | B27: =L27&"-"&TEXT(P27,"0000") -> 20220117-0900 | C27: 데스크톱 | D27: 활용중 | E27: 학생용 | F27: DG375-GA31-0BPS | G27: 삼보 | H27: =IFERROR(VLOOKUP(O27,'정보화기기 명부'!A$2:B$187,2,FALSE),"") -> 정보과학실 | I27: =IFERROR(VLOOKUP(O27,'학생용 IP'!$C$11:$H$326,5,FALSE),"") -> 10.54.36.22 | L27: 20220117 | M27: 587000 | N27: 자체구매 | O27: 정보과학실 학생용 8 | P27: 900 | Q27: WINDOW 10
A28: =O28 -> 정보과학실 학생용 7 | B28: =L28&"-"&TEXT(P28,"0000") -> 20220117-0899 | C28: 데스크톱 | D28: 활용중 | E28: 학생용 | F28: DG375-GA31-0BPS | G28: 삼보 | H28: =IFERROR(VLOOKUP(O28,'정보화기기 명부'!A$2:B$187,2,FALSE),"") -> 정보과학실 | I28: =IFERROR(VLOOKUP(O28,'학생용 IP'!$C$11:$H$326,5,FALSE),"") -> 10.54.36.21 | L28: 20220117 | M28: 587000 | N28: 자체구매 | O28: 정보과학실 학생용 7 | P28: 899 | Q28: WINDOW 10
A29: =O29 -> 정보과학실 학생용 6 | B29: =L29&"-"&TEXT(P29,"0000") -> 20220117-0898 | C29: 데스크톱 | D29: 활용중 | E29: 학생용 | F29: DG375-GA31-0BPS | G29: 삼보 | H29: =IFERROR(VLOOKUP(O29,'정보화기기 명부'!A$2:B$187,2,FALSE),"") -> 정보과학실 | I29: =IFERROR(VLOOKUP(O29,'학생용 IP'!$C$11:$H$326,5,FALSE),"") -> 10.54.36.20 | L29: 20220117 | M29: 587000 | N29: 자체구매 | O29: 정보과학실 학생용 6 | P29: 898 | Q29: WINDOW 10
A30: =O30 -> 정보과학실 학생용 5 | B30: =L30&"-"&TEXT(P30,"0000") -> 20220117-0897 | C30: 데스크톱 | D30: 활용중 | E30: 학생용 | F30: DG375-GA31-0BPS | G30: 삼보 | H30: =IFERROR(VLOOKUP(O30,'정보화기기 명부'!A$2:B$187,2,FALSE),"") -> 정보과학실 | I30: =IFERROR(VLOOKUP(O30,'학생용 IP'!$C$11:$H$326,5,FALSE),"") -> 10.54.36.19 | L30: 20220117 | M30: 587000 | N30: 자체구매 | O30: 정보과학실 학생용 5 | P30: 897 | Q30: WINDOW 10
A31: =O31 -> 정보과학실 학생용 4 | B31: =L31&"-"&TEXT(P31,"0000") -> 20220117-0896 | C31: 데스크톱 | D31: 활용중 | E31: 학생용 | F31: DG375-GA31-0BPS | G31: 삼보 | H31: =IFERROR(VLOOKUP(O31,'정보화기기 명부'!A$2:B$187,2,FALSE),"") -> 정보과학실 | I31: =IFERROR(VLOOKUP(O31,'학생용 IP'!$C$11:$H$326,5,FALSE),"") -> 10.54.36.18 | L31: 20220117 | M31: 587000 | N31: 자체구매 | O31: 정보과학실 학생용 4 | P31: 896 | Q31: WINDOW 10
A32: =O32 -> 교사 예비용 17 | B32: =L32&"-"&TEXT(P32,"0000") -> 20210823-0886 | C32: 노트북 | D32: 활용중 | E32: 교원용 | F32: NT550XDA-KG03G | G32: 삼성 | H32: =IFERROR(VLOOKUP(O32,'정보화기기 명부'!A$2:B$187,2,FALSE),"") | I32: =IFERROR(VLOOKUP(O32,'교직원용 IP'!$C$2:$H$230,6,FALSE),"") | L32: 20210823 | M32: 855000 | N32: 자체구매 | O32: 교사 예비용 17 | P32: 886 | Q32: WINDOW 10 | S32: 8GB | T32: 500GB
A33: =O33 -> 교사 예비용 16 | B33: =L33&"-"&TEXT(P33,"0000") -> 20210823-0887 | C33: 노트북 | D33: 활용중 | E33: 교원용 | F33: NT550XDA-KG03G | G33: 삼성 | H33: =IFERROR(VLOOKUP(O33,'정보화기기 명부'!A$2:B$187,2,FALSE),"") | I33: =IFERROR(VLOOKUP(O33,'교직원용 IP'!$C$2:$H$230,6,FALSE),"") | L33: 20210823 | M33: 855000 | N33: 자체구매 | O33: 교사 예비용 16 | P33: 887 | Q33: WINDOW 10 | S33: 8GB | T33: 500GB
A34: =O34 -> 황경환 교감선생님 | B34: =L34&"-"&TEXT(P34,"0000") -> 20210823-0888 | C34: 노트북 | D34: 활용중 | E34: 교원용 | F34: NT550XDA-KG03G | G34: 삼성 | H34: =IFERROR(VLOOKUP(O34,'정보화기기 명부'!A$2:B$187,2,FALSE),"") | I34: =IFERROR(VLOOKUP(O34,'교직원용 IP'!$C$2:$H$230,6,FALSE),"") -> 10.51.90.180 | L34: 20210823 | M34: 855000 | N34: 자체구매 | O34: 황경환 교감선생님 | P34: 888 | Q34: WINDOW 10 | S34: 8GB | T34: 500GB
A35: =O35 -> 교사 예비용 15 | B35: =L35&"-"&TEXT(P35,"0000") -> 20210823-0889 | C35: 노트북 | D35: 활용중 | E35: 교원용 | F35: NT550XDA-KG03G | G35: 삼성 | H35: =IFERROR(VLOOKUP(O35,'정보화기기 명부'!A$2:B$187,2,FALSE),"") | I35: =IFERROR(VLOOKUP(O35,'교직원용 IP'!$C$2:$H$230,6,FALSE),"") | L35: 20210823 | M35: 855000 | N35: 자체구매 | O35: 교사 예비용 15 | P35: 889 | Q35: WINDOW 10 | S35: 8GB | T35: 500GB
A36: =O36 -> 교사 예비용9 | B36: =L36&"-"&TEXT(P36,"0000") -> 20210823-0890 | C36: 노트북 | D36: 활용중 | E36: 교원용 | F36: NT550XDA-KG03G | G36: 삼성 | H36: =IFERROR(VLOOKUP(O36,'정보화기기 명부'!A$2:B$187,2,FALSE),"") | I36: =IFERROR(VLOOKUP(O36,'교직원용 IP'!$C$2:$H$230,6,FALSE),"") | L36: 20210823 | M36: 855000 | N36: 자체구매 | O36: 교사 예비용9 | P36: 890 | Q36: WINDOW 10 | S36: 8GB | T36: 500GB
A37: =O37 -> 교사 예비용 14 | B37: =L37&"-"&TEXT(P37,"0000") -> 20210823-0891 | C37: 노트북 | D37: 활용중 | E37: 교원용 | F37: NT550XDA-KG03G | G37: 삼성 | H37: =IFERROR(VLOOKUP(O37,'정보화기기 명부'!A$2:B$187,2,FALSE),"") | I37: =IFERROR(VLOOKUP(O37,'교직원용 IP'!$C$2:$H$230,6,FALSE),"") | L37: 20210823 | M37: 855000 | N37: 자체구매 | O37: 교사 예비용 14 | P37: 891 | Q37: WINDOW 10 | S37: 8GB | T37: 500GB
A38: =O38 -> 교사 예비용 13 | B38: =L38&"-"&TEXT(P38,"0000") -> 20210823-0892 | C38: 노트북 | D38: 활용중 | E38: 교원용 | F38: NT550XDA-KG03G | G38: 삼성 | H38: =IFERROR(VLOOKUP(O38,'정보화기기 명부'!A$2:B$187,2,FALSE),"") | I38: =IFERROR(VLOOKUP(O38,'교직원용 IP'!$C$2:$H$230,6,FALSE),"") | L38: 20210823 | M38: 855000 | N38: 자체구매 | O38: 교사 예비용 13 | P38: 892 | Q38: WINDOW 10 | S38: 8GB | T38: 500GB
A39: =O39 -> 교사 예비용 12 | B39: =L39&"-"&TEXT(P39,"0000") -> 20210823-0893 | C39: 노트북 | D39: 활용중 | E39: 교원용 | F39: NT550XDA-KG03G | G39: 삼성 | H39: =IFERROR(VLOOKUP(O39,'정보화기기 명부'!A$2:B$187,2,FALSE),"") | I39: =IFERROR(VLOOKUP(O39,'교직원용 IP'!$C$2:$H$230,6,FALSE),"") | L39: 20210823 | M39: 855000 | N39: 자체구매 | O39: 교사 예비용 12 | P39: 893 | Q39: WINDOW 10 | S39: 8GB | T39: 500GB
A40: =O40 -> 체육관방송용 | B40: =L40&"-"&TEXT(P40,"0000") -> 20210823-0894 | C40: 노트북 | D40: 활용중 | E40: 교원용 | F40: NT550XDA-KG03G | G40: 삼성 | H40: =IFERROR(VLOOKUP(O40,'정보화기기 명부'!A$2:B$187,2,FALSE),"") | I40: =IFERROR(VLOOKUP(O40,'교직원용 IP'!$C$2:$H$230,6,FALSE),"") -> 10.51.90.198 | L40: 20210823 | M40: 855000 | N40: 자체구매 | O40: 체육관방송용 | P40: 894 | Q40: WINDOW 10 | S40: 8GB | T40: 500GB
...

Sheet 메일머지용
A1: =PC!B1 -> 관리번호 | B1: =PC!E1 -> 관리유형 | C1: =PC!G1 -> 제조회사 | D1: =PC!F1 -> 모델명 | E1: =PC!H1 -> 관리실 | F1: =PC!M1 -> 구입금액 | G1: =PC!L1 -> 구입일자 | H1: =PC!O1 -> 관리자명
A2: =VLOOKUP($H2,PC!$A$1:$M$272,2,FALSE) -> 20210823-0894 | B2: =VLOOKUP($H2,PC!$A$1:$O$272,5,FALSE) -> 교원용 | C2: =VLOOKUP($H2,PC!$A$1:$O$272,7,FALSE) -> 삼성 | D2: =VLOOKUP($H2,PC!$A$1:$O$272,6,FALSE) -> NT550XDA-KG03G | E2: =VLOOKUP($H2,PC!$A$1:$O$272,8,FALSE) | F2: =VLOOKUP($H2,PC!$A$1:$O$272,13,FALSE) -> 855000 | G2: =VLOOKUP($H2,PC!$A$1:$O$272,12,FALSE) -> 20210823 | H2: 체육관방송용
A3: =VLOOKUP($H3,PC!$A$1:$M$272,2,FALSE) -> 20200901-0848 | B3: =VLOOKUP($H3,PC!$A$1:$O$272,5,FALSE) -> 교원용 | C3: =VLOOKUP($H3,PC!$A$1:$O$272,7,FALSE) -> 삼성 | D3: =VLOOKUP($H3,PC!$A$1:$O$272,6,FALSE) -> 0 | E3: =VLOOKUP($H3,PC!$A$1:$O$272,8,FALSE) -> 0 | F3: =VLOOKUP($H3,PC!$A$1:$O$272,13,FALSE) -> 820000 | G3: =VLOOKUP($H3,PC!$A$1:$O$272,12,FALSE) -> 20200901 | H3: 교사 예비용 11

Sheet 교직원용 IP
A1: IP | C1: 셩명 | D1: 부서 | E1: 관리번호 | F1: 모델명 | G1: PC 구분
A2: 10.51.90. | B2: 71 | C2: 우현주 | D2: =IFERROR(VLOOKUP(C2,'정보화기기 명부'!A$2:B$138,2,FALSE),"") -> 교장실 | E2: =IFERROR(VLOOKUP(C2,PC!A$1:K$435,2,FALSE),"") -> 20210111-0884 | F2: =IFERROR(VLOOKUP(C2,PC!A$1:K$435,7,FALSE)&" "&VLOOKUP(C2,PC!A$1:K$435,6,FALSE),"") -> 늑대와여우컴퓨터 NY-Q95PE00D | G2: =IFERROR(VLOOKUP(C2,PC!$A$1:$K$435,3,FALSE),"") -> 데스크톱 | H2: =$A$2&B2 -> 10.51.90.71
B3: 72 | C3: 황경환 | D3: =IFERROR(VLOOKUP(C3,'정보화기기 명부'!A$2:B$138,2,FALSE),"") -> 2층 교무실 | E3: =IFERROR(VLOOKUP(C3,PC!A$1:K$435,2,FALSE),"") -> 20230721-0903 | F3: =IFERROR(VLOOKUP(C3,PC!A$1:K$435,7,FALSE)&" "&VLOOKUP(C3,PC!A$1:K$435,6,FALSE),"") -> 삼보 DG481-GA51-011, Intel Core i5 12500(3GHz) | G3: =IFERROR(VLOOKUP(C3,PC!$A$1:$K$435,3,FALSE),"") -> 데스크톱 | H3: =$A$2&B3 -> 10.51.90.72
B4: 73 | C4: 백양현 | D4: =IFERROR(VLOOKUP(C4,'정보화기기 명부'!A$2:B$138,2,FALSE),"") -> 교육행정실 | E4: =IFERROR(VLOOKUP(C4,PC!A$1:K$435,2,FALSE),"") -> 20220117-0902 | F4: =IFERROR(VLOOKUP(C4,PC!A$1:K$435,7,FALSE)&" "&VLOOKUP(C4,PC!A$1:K$435,6,FALSE),"") -> 삼보 DG375-GA31-0BPS | G4: =IFERROR(VLOOKUP(C4,PC!$A$1:$K$435,3,FALSE),"") -> 데스크톱 | H4: =$A$2&B4 -> 10.51.90.73
B5: 74 | C5: 임향민 | D5: =IFERROR(VLOOKUP(C5,'정보화기기 명부'!A$2:B$138,2,FALSE),"") -> 교육행정실 | E5: =IFERROR(VLOOKUP(C5,PC!A$1:K$435,2,FALSE),"") -> 20231219-0904 | F5: =IFERROR(VLOOKUP(C5,PC!A$1:K$435,7,FALSE)&" "&VLOOKUP(C5,PC!A$1:K$435,6,FALSE),"") -> 삼보 DR281-GS51-012 intel core i5 | G5: =IFERROR(VLOOKUP(C5,PC!$A$1:$K$435,3,FALSE),"") -> 데스크톱 | H5: =$A$2&B5 -> 10.51.90.74 | I5: 임향민
B6: 75 | C6: 김이조 | D6: =IFERROR(VLOOKUP(C6,'정보화기기 명부'!A$2:B$138,2,FALSE),"") -> 교육행정실 | E6: =IFERROR(VLOOKUP(C6,PC!A$1:K$435,2,FALSE),"") -> 20220117-0901 | F6: =IFERROR(VLOOKUP(C6,PC!A$1:K$435,7,FALSE)&" "&VLOOKUP(C6,PC!A$1:K$435,6,FALSE),"") -> 삼보 DG375-GA31-0BPS | G6: =IFERROR(VLOOKUP(C6,PC!$A$1:$K$435,3,FALSE),"") -> 데스크톱 | H6: =$A$2&B6 -> 10.51.90.75 | I6: 김이조
B7: 76 | C7: 정은영 | D7: =IFERROR(VLOOKUP(C7,'정보화기기 명부'!A$2:B$138,2,FALSE),"") -> 교육행정실 | E7: =IFERROR(VLOOKUP(C7,PC!A$1:K$435,2,FALSE),"") -> 20210512-0885 | F7: =IFERROR(VLOOKUP(C7,PC!A$1:K$435,7,FALSE)&" "&VLOOKUP(C7,PC!A$1:K$435,6,FALSE),"") -> 성주컴텍 TD210-GCL23S | G7: =IFERROR(VLOOKUP(C7,PC!$A$1:$K$435,3,FALSE),"") -> 데스크톱 | H7: =$A$2&B7 -> 10.51.90.76 | I7: 정은영
B8: 77 | C8: 성윤정 | D8: =IFERROR(VLOOKUP(C8,'정보화기기 명부'!A$2:B$138,2,FALSE),"") -> 교육행정실 | E8: =IFERROR(VLOOKUP(C8,PC!A$1:K$435,2,FALSE),"") -> 20250708-0805 | F8: =IFERROR(VLOOKUP(C8,PC!A$1:K$435,7,FALSE)&" "&VLOOKUP(C8,PC!A$1:K$435,6,FALSE),"") -> 대우루컴즈 DS361A-245430 | G8: =IFERROR(VLOOKUP(C8,PC!$A$1:$K$435,3,FALSE),"") -> 데스크톱 | H8: =$A$2&B8 -> 10.51.90.77 | I8: 성윤정
B9: 78 | C9: 심경옥 | D9: =IFERROR(VLOOKUP(C9,'정보화기기 명부'!A$2:B$138,2,FALSE),"") -> 교육행정실 | E9: =IFERROR(VLOOKUP(C9,PC!A$1:K$435,2,FALSE),"") | F9: =IFERROR(VLOOKUP(C9,PC!A$1:K$435,7,FALSE)&" "&VLOOKUP(C9,PC!A$1:K$435,6,FALSE),"") | G9: =IFERROR(VLOOKUP(C9,PC!$A$1:$K$435,3,FALSE),"") | H9: =$A$2&B9 -> 10.51.90.78 | I9: 심경옥
B10: 79 | C10: 이주선 | D10: =IFERROR(VLOOKUP(C10,'정보화기기 명부'!A$2:B$138,2,FALSE),"") -> 급식실 | E10: =IFERROR(VLOOKUP(C10,PC!A$1:K$435,2,FALSE),"") -> 20190927-0804 | F10: =IFERROR(VLOOKUP(C10,PC!A$1:K$435,7,FALSE)&" "&VLOOKUP(C10,PC!A$1:K$435,6,FALSE),"") -> 레드스톤 VITO RMS-565S | G10: =IFERROR(VLOOKUP(C10,PC!$A$1:$K$435,3,FALSE),"") -> 데스크톱 | H10: =$A$2&B10 -> 10.51.90.79
B11: 80 | C11: 김종익 | D11: =IFERROR(VLOOKUP(C11,'정보화기기 명부'!A$2:B$138,2,FALSE),"") -> 시설관리실 | E11: =IFERROR(VLOOKUP(C11,PC!A$1:K$435,2,FALSE),"") -> 20250708-0803 | F11: =IFERROR(VLOOKUP(C11,PC!A$1:K$435,7,FALSE)&" "&VLOOKUP(C11,PC!A$1:K$435,6,FALSE),"") -> 대우루컴즈 DS361A-245430 | G11: =IFERROR(VLOOKUP(C11,PC!$A$1:$K$435,3,FALSE),"") -> 데스크톱 | H11: =$A$2&B11 -> 10.51.90.80
B12: 81 | C12: 윤선영 | D12: =IFERROR(VLOOKUP(C12,'정보화기기 명부'!A$2:B$138,2,FALSE),"") -> 1학년부 | E12: =IFERROR(VLOOKUP(C12,PC!A$1:K$435,2,FALSE),"") -> 20220829-0907 | F12: =IFERROR(VLOOKUP(C12,PC!A$1:K$435,7,FALSE)&" "&VLOOKUP(C12,PC!A$1:K$435,6,FALSE),"") -> 삼보 N5800-G050-OU02 | G12: =IFERROR(VLOOKUP(C12,PC!$A$1:$K$435,3,FALSE),"") -> 노트북 | H12: =$A$2&B12 -> 10.51.90.81
B13: 82 | C13: 유영복 | D13: =IFERROR(VLOOKUP(C13,'정보화기기 명부'!A$2:B$138,2,FALSE),"") -> 3학년부 | E13: =IFERROR(VLOOKUP(C13,PC!A$1:K$435,2,FALSE),"") | F13: =IFERROR(VLOOKUP(C13,PC!A$1:K$435,7,FALSE)&" "&VLOOKUP(C13,PC!A$1:K$435,6,FALSE),"") | G13: =IFERROR(VLOOKUP(C13,PC!$A$1:$K$435,3,FALSE),"") | H13: =$A$2&B13 -> 10.51.90.82
B14: 83 | C14: 고진아 | D14: =IFERROR(VLOOKUP(C14,'정보화기기 명부'!A$2:B$138,2,FALSE),"") -> 혁신교육부 | E14: =IFERROR(VLOOKUP(C14,PC!A$1:K$435,2,FALSE),"") -> 20230315-0919 | F14: =IFERROR(VLOOKUP(C14,PC!A$1:K$435,7,FALSE)&" "&VLOOKUP(C14,PC!A$1:K$435,6,FALSE),"") -> 삼성 NT550XED-KG03G | G14: =IFERROR(VLOOKUP(C14,PC!$A$1:$K$435,3,FALSE),"") -> 노트북 | H14: =$A$2&B14 -> 10.51.90.83
B15: 84 | C15: 김두순 | D15: =IFERROR(VLOOKUP(C15,'정보화기기 명부'!A$2:B$138,2,FALSE),"") -> 수리과학부 | E15: =IFERROR(VLOOKUP(C15,PC!A$1:K$435,2,FALSE),"") -> 20230315-0920 | F15: =IFERROR(VLOOKUP(C15,PC!A$1:K$435,7,FALSE)&" "&VLOOKUP(C15,PC!A$1:K$435,6,FALSE),"") -> 삼성 NT550XED-KG03G | G15: =IFERROR(VLOOKUP(C15,PC!$A$1:$K$435,3,FALSE),"") -> 노트북 | H15: =$A$2&B15 -> 10.51.90.84
B16: 85 | C16: 중앙제어 | D16: =IFERROR(VLOOKUP(C16,'정보화기기 명부'!A$2:B$138,2,FALSE),"") | E16: =IFERROR(VLOOKUP(C16,PC!A$1:K$435,2,FALSE),"") | F16: =IFERROR(VLOOKUP(C16,PC!A$1:K$435,7,FALSE)&" "&VLOOKUP(C16,PC!A$1:K$435,6,FALSE),"") | G16: =IFERROR(VLOOKUP(C16,PC!$A$1:$K$435,3,FALSE),"") | H16: =$A$2&B16 -> 10.51.90.85
B17: 86 | C17: 정다운 | D17: =IFERROR(VLOOKUP(C17,'정보화기기 명부'!A$2:B$138,2,FALSE),"") -> 2층 교무실 | E17: =IFERROR(VLOOKUP(C17,PC!A$1:K$435,2,FALSE),"") -> 20190927-0806 | F17: =IFERROR(VLOOKUP(C17,PC!A$1:K$435,7,FALSE)&" "&VLOOKUP(C17,PC!A$1:K$435,6,FALSE),"") -> 레드스톤 VITO RMS-565S | G17: =IFERROR(VLOOKUP(C17,PC!$A$1:$K$435,3,FALSE),"") -> 데스크톱 | H17: =$A$2&B17 -> 10.51.90.86 | I17: 황영선
B18: 87 | C18: 원선일 | D18: =IFERROR(VLOOKUP(C18,'정보화기기 명부'!A$2:B$138,2,FALSE),"") -> 2층 교무실 | E18: =IFERROR(VLOOKUP(C18,PC!A$1:K$435,2,FALSE),"") -> 20180601-0777 | F18: =IFERROR(VLOOKUP(C18,PC!A$1:K$435,7,FALSE)&" "&VLOOKUP(C18,PC!A$1:K$435,6,FALSE),"") -> 늑대와여우컴퓨터 WFG-H116FC-IGTB | G18: =IFERROR(VLOOKUP(C18,PC!$A$1:$K$435,3,FALSE),"") -> 데스크톱 | H18: =$A$2&B18 -> 10.51.90.87
B19: 88 | C19: - | D19: =IFERROR(VLOOKUP(C19,'정보화기기 명부'!A$2:B$138,2,FALSE),"") | E19: =IFERROR(VLOOKUP(C19,PC!A$1:K$435,2,FALSE),"") | F19: =IFERROR(VLOOKUP(C19,PC!A$1:K$435,7,FALSE)&" "&VLOOKUP(C19,PC!A$1:K$435,6,FALSE),"") | G19: =IFERROR(VLOOKUP(C19,PC!$A$1:$K$435,3,FALSE),"") | H19: =$A$2&B19 -> 10.51.90.88
B20: 89 | C20: 최용순 | D20: =IFERROR(VLOOKUP(C20,'정보화기기 명부'!A$2:B$138,2,FALSE),"") -> 교무기획부 | E20: =IFERROR(VLOOKUP(C20,PC!A$1:K$435,2,FALSE),"") | F20: =IFERROR(VLOOKUP(C20,PC!A$1:K$435,7,FALSE)&" "&VLOOKUP(C20,PC!A$1:K$435,6,FALSE),"") | G20: =IFERROR(VLOOKUP(C20,PC!$A$1:$K$435,3,FALSE),"") | H20: =$A$2&B20 -> 10.51.90.89
B21: 90 | C21: 수업분석실 | D21: =IFERROR(VLOOKUP(C21,'정보화기기 명부'!A$2:B$138,2,FALSE),"") -> 수업분석실 | E21: =IFERROR(VLOOKUP(C21,PC!A$1:K$435,2,FALSE),"") | F21: =IFERROR(VLOOKUP(C21,PC!A$1:K$435,7,FALSE)&" "&VLOOKUP(C21,PC!A$1:K$435,6,FALSE),"") | G21: =IFERROR(VLOOKUP(C21,PC!$A$1:$K$435,3,FALSE),"") | H21: =$A$2&B21 -> 10.51.90.90
B22: 91 | C22: 나정훈 | D22: =IFERROR(VLOOKUP(C22,'정보화기기 명부'!A$2:B$138,2,FALSE),"") -> 1학년부 | E22: =IFERROR(VLOOKUP(C22,PC!A$1:K$435,2,FALSE),"") | F22: =IFERROR(VLOOKUP(C22,PC!A$1:K$435,7,FALSE)&" "&VLOOKUP(C22,PC!A$1:K$435,6,FALSE),"") | G22: =IFERROR(VLOOKUP(C22,PC!$A$1:$K$435,3,FALSE),"") | H22: =$A$2&B22 -> 10.51.90.91
B23: 92 | C23: 유미라 | D23: =IFERROR(VLOOKUP(C23,'정보화기기 명부'!A$2:B$138,2,FALSE),"") -> 진로진학상담부 | E23: =IFERROR(VLOOKUP(C23,PC!A$1:K$435,2,FALSE),"") | F23: =IFERROR(VLOOKUP(C23,PC!A$1:K$435,7,FALSE)&" "&VLOOKUP(C23,PC!A$1:K$435,6,FALSE),"") | G23: =IFERROR(VLOOKUP(C23,PC!$A$1:$K$435,3,FALSE),"") | H23: =$A$2&B23 -> 10.51.90.92
A24: X | B24: 93 | C24: 구 김현우 | D24: =IFERROR(VLOOKUP(C24,'정보화기기 명부'!A$2:B$138,2,FALSE),"") | E24: =IFERROR(VLOOKUP(C24,PC!A$1:K$435,2,FALSE),"") | F24: =IFERROR(VLOOKUP(C24,PC!A$1:K$435,7,FALSE)&" "&VLOOKUP(C24,PC!A$1:K$435,6,FALSE),"") | G24: =IFERROR(VLOOKUP(C24,PC!$A$1:$K$435,3,FALSE),"") | H24: =$A$2&B24 -> 10.51.90.93
B25: 94 | C25: 김세연 | D25: =IFERROR(VLOOKUP(C25,'정보화기기 명부'!A$2:B$138,2,FALSE),"") -> 3학년부 | E25: =IFERROR(VLOOKUP(C25,PC!A$1:K$435,2,FALSE),"") | F25: =IFERROR(VLOOKUP(C25,PC!A$1:K$435,7,FALSE)&" "&VLOOKUP(C25,PC!A$1:K$435,6,FALSE),"") | G25: =IFERROR(VLOOKUP(C25,PC!$A$1:$K$435,3,FALSE),"") | H25: =$A$2&B25 -> 10.51.90.94
B26: 95 | C26: 손승태 | D26: =IFERROR(VLOOKUP(C26,'정보화기기 명부'!A$2:B$138,2,FALSE),"") | E26: =IFERROR(VLOOKUP(C26,PC!A$1:K$435,2,FALSE),"") | F26: 삼성NT750XGK-KG71G | G26: =IFERROR(VLOOKUP(C26,PC!$A$1:$K$435,3,FALSE),"") | H26: =$A$2&B26 -> 10.51.90.95
B27: 96 | C27: 한혜숙 | D27: =IFERROR(VLOOKUP(C27,'정보화기기 명부'!A$2:B$138,2,FALSE),"") -> 2학년부 | E27: =IFERROR(VLOOKUP(C27,PC!A$1:K$435,2,FALSE),"") | F27: =IFERROR(VLOOKUP(C27,PC!A$1:K$435,7,FALSE)&" "&VLOOKUP(C27,PC!A$1:K$435,6,FALSE),"") | G27: =IFERROR(VLOOKUP(C27,PC!$A$1:$K$435,3,FALSE),"") | H27: =$A$2&B27 -> 10.51.90.96
B28: 97 | C28: 노병철 | D28: =IFERROR(VLOOKUP(C28,'정보화기기 명부'!A$2:B$138,2,FALSE),"") -> 1학년부 | E28: =IFERROR(VLOOKUP(C28,PC!A$1:K$435,2,FALSE),"") | F28: 삼성NT750XGK-KG71G | G28: =IFERROR(VLOOKUP(C28,PC!$A$1:$K$435,3,FALSE),"") | H28: =$A$2&B28 -> 10.51.90.97
B29: 98 | C29: 성적처리용 | D29: =IFERROR(VLOOKUP(C29,'정보화기기 명부'!A$2:B$138,2,FALSE),"") -> 교무기획부 | E29: =IFERROR(VLOOKUP(C29,PC!A$1:K$435,2,FALSE),"") -> 20180521-0776 | F29: =IFERROR(VLOOKUP(C29,PC!A$1:K$435,7,FALSE)&" "&VLOOKUP(C29,PC!A$1:K$435,6,FALSE),"") -> 주연테크 JY-AX44P5G | G29: =IFERROR(VLOOKUP(C29,PC!$A$1:$K$435,3,FALSE),"") -> 데스크톱 | H29: =$A$2&B29 -> 10.51.90.98
B30: 99 | C30: 김용천 | D30: =IFERROR(VLOOKUP(C30,'정보화기기 명부'!A$2:B$138,2,FALSE),"") -> 학생인권안전부 | E30: =IFERROR(VLOOKUP(C30,PC!A$1:K$435,2,FALSE),"") | F30: =IFERROR(VLOOKUP(C30,PC!A$1:K$435,7,FALSE)&" "&VLOOKUP(C30,PC!A$1:K$435,6,FALSE),"") | G30: =IFERROR(VLOOKUP(C30,PC!$A$1:$K$435,3,FALSE),"") | H30: =$A$2&B30 -> 10.51.90.99
B31: 100 | C31: 파일 서버 | D31: =IFERROR(VLOOKUP(C31,'정보화기기 명부'!A$2:B$138,2,FALSE),"") -> 정보교육부 | E31: =IFERROR(VLOOKUP(C31,PC!A$1:K$435,2,FALSE),"") -> 20190927-0802 | F31: =IFERROR(VLOOKUP(C31,PC!A$1:K$435,7,FALSE)&" "&VLOOKUP(C31,PC!A$1:K$435,6,FALSE),"") -> 레드스톤 VITO RMS-565S | G31: =IFERROR(VLOOKUP(C31,PC!$A$1:$K$435,3,FALSE),"") -> 데스크톱 | H31: =$A$2&B31 -> 10.51.90.100 | J31: 파일서버
B32: 101 | C32: 윤샤롬 | D32: =IFERROR(VLOOKUP(C32,'정보화기기 명부'!A$2:B$138,2,FALSE),"") -> 3학년부 | E32: =IFERROR(VLOOKUP(C32,PC!A$1:K$435,2,FALSE),"") -> 20230315-0921 | F32: =IFERROR(VLOOKUP(C32,PC!A$1:K$435,7,FALSE)&" "&VLOOKUP(C32,PC!A$1:K$435,6,FALSE),"") -> 삼성 NT550XED-KG03G | G32: =IFERROR(VLOOKUP(C32,PC!$A$1:$K$435,3,FALSE),"") -> 노트북 | H32: =$A$2&B32 -> 10.51.90.101 | J32: 사용자 | K32: 암호
B33: 102 | C33: 임숙진 | D33: =IFERROR(VLOOKUP(C33,'정보화기기 명부'!A$2:B$138,2,FALSE),"") -> 혁신교육부 | E33: =IFERROR(VLOOKUP(C33,PC!A$1:K$435,2,FALSE),"") -> 20220829-0912 | F33: =IFERROR(VLOOKUP(C33,PC!A$1:K$435,7,FALSE)&" "&VLOOKUP(C33,PC!A$1:K$435,6,FALSE),"") -> 삼보 N5800-G050-OU02 | G33: =IFERROR(VLOOKUP(C33,PC!$A$1:$K$435,3,FALSE),"") -> 노트북 | H33: =$A$2&B33 -> 10.51.90.102 | J33: administrator | K33: ic2018#
B34: 103 | C34: 강민정 | D34: =IFERROR(VLOOKUP(C34,'정보화기기 명부'!A$2:B$138,2,FALSE),"") -> 2학년부 | E34: =IFERROR(VLOOKUP(C34,PC!A$1:K$435,2,FALSE),"") | F34: =IFERROR(VLOOKUP(C34,PC!A$1:K$435,7,FALSE)&" "&VLOOKUP(C34,PC!A$1:K$435,6,FALSE),"") | G34: =IFERROR(VLOOKUP(C34,PC!$A$1:$K$435,3,FALSE),"") | H34: =$A$2&B34 -> 10.51.90.103 | J34: 시간표 | K34: ic#2018 | L34: inchang | M34: 5519305
B35: 104 | C35: 이준호 | D35: =IFERROR(VLOOKUP(C35,'정보화기기 명부'!A$2:B$138,2,FALSE),"") -> 정보교육부 | E35: =IFERROR(VLOOKUP(C35,PC!A$1:K$435,2,FALSE),"") | F35: =IFERROR(VLOOKUP(C35,PC!A$1:K$435,7,FALSE)&" "&VLOOKUP(C35,PC!A$1:K$435,6,FALSE),"") | G35: =IFERROR(VLOOKUP(C35,PC!$A$1:$K$435,3,FALSE),"") | H35: =$A$2&B35 -> 10.51.90.104 | J35: staff | K35: sta#ff2018
B36: 105 | C36: 김정아 | D36: =IFERROR(VLOOKUP(C36,'정보화기기 명부'!A$2:B$138,2,FALSE),"") -> 체육보건부 | E36: =IFERROR(VLOOKUP(C36,PC!A$1:K$435,2,FALSE),"") | F36: =IFERROR(VLOOKUP(C36,PC!A$1:K$435,7,FALSE)&" "&VLOOKUP(C36,PC!A$1:K$435,6,FALSE),"") | G36: =IFERROR(VLOOKUP(C36,PC!$A$1:$K$435,3,FALSE),"") | H36: =$A$2&B36 -> 10.51.90.105 | J36: cool | K36: ic2018#
B37: 106 | C37: 진국현 | D37: =IFERROR(VLOOKUP(C37,'정보화기기 명부'!A$2:B$138,2,FALSE),"") | E37: =IFERROR(VLOOKUP(C37,PC!A$1:K$435,2,FALSE),"") -> 20190927-0801 | F37: =IFERROR(VLOOKUP(C37,PC!A$1:K$435,7,FALSE)&" "&VLOOKUP(C37,PC!A$1:K$435,6,FALSE),"") -> 레드스톤 VITO RMS-565S | G37: =IFERROR(VLOOKUP(C37,PC!$A$1:$K$435,3,FALSE),"") -> 데스크톱 | H37: =$A$2&B37 -> 10.51.90.106 | J37: 진국현 | K37: MS계정 암호
B38: 107 | C38: 유희정 | D38: =IFERROR(VLOOKUP(C38,'정보화기기 명부'!A$2:B$138,2,FALSE),"") -> 정보교육부 | E38: =IFERROR(VLOOKUP(C38,PC!A$1:K$435,2,FALSE),"") -> 20220308-0903 | F38: =IFERROR(VLOOKUP(C38,PC!A$1:K$435,7,FALSE)&" "&VLOOKUP(C38,PC!A$1:K$435,6,FALSE),"") -> 삼성 NT550XDA-KG01G | G38: =IFERROR(VLOOKUP(C38,PC!$A$1:$K$435,3,FALSE),"") -> 노트북 | H38: =$A$2&B38 -> 10.51.90.107 | J38: 인창고 | K38: 인#18
B39: 108 | C39: 전부영 | D39: =IFERROR(VLOOKUP(C39,'정보화기기 명부'!A$2:B$138,2,FALSE),"") -> 교무기획부 | E39: =IFERROR(VLOOKUP(C39,PC!A$1:K$435,2,FALSE),"") | F39: =IFERROR(VLOOKUP(C39,PC!A$1:K$435,7,FALSE)&" "&VLOOKUP(C39,PC!A$1:K$435,6,FALSE),"") | G39: =IFERROR(VLOOKUP(C39,PC!$A$1:$K$435,3,FALSE),"") | H39: =$A$2&B39 -> 10.51.90.108
B40: 109 | C40: 정진희 | D40: =IFERROR(VLOOKUP(C40,'정보화기기 명부'!A$2:B$138,2,FALSE),"") -> 교육과정부 | E40: =IFERROR(VLOOKUP(C40,PC!A$1:K$435,2,FALSE),"") | F40: =IFERROR(VLOOKUP(C40,PC!A$1:K$435,7,FALSE)&" "&VLOOKUP(C40,PC!A$1:K$435,6,FALSE),"") | G40: =IFERROR(VLOOKUP(C40,PC!$A$1:$K$435,3,FALSE),"") | H40: =$A$2&B40 -> 10.51.90.109
...

Sheet 학생용 IP
A1: 대역 | B1: IP | C1: 관리자 | D1: 기 종 | E1: 관리번호
A2: 10.54.36. | B2: 1 | G2: =$A$2&B2 -> 10.54.36.1
B3: 2 | G3: =$A$2&B3 -> 10.54.36.2
B4: 3 | G4: =$A$2&B4 -> 10.54.36.3
B5: 4 | G5: =$A$2&B5 -> 10.54.36.4
B6: 5 | G6: =$A$2&B6 -> 10.54.36.5
B7: 6 | G7: =$A$2&B7 -> 10.54.36.6
B8: 7 | G8: =$A$2&B8 -> 10.54.36.7
B9: 8 | G9: =$A$2&B9 -> 10.54.36.8
B10: 9 | G10: =$A$2&B10 -> 10.54.36.9
B11: 10 | C11: 정보과학실 교사용 | D11: =IFERROR((VLOOKUP(C11,PC!$A$1:$K$435,7,FALSE)&" "&VLOOKUP(C11,PC!$A$1:$K$435,6,FALSE)),"") -> 레드스톤 VITO RMS-565S | E11: =IFERROR(VLOOKUP(C11,PC!$A$1:$K$435,2,FALSE),"") -> 20190927-0798 | F11: 수리과학부 | G11: =$A$2&B11 -> 10.54.36.10
B12: 11 | C12: 지구과학실험실 교사용 | D12: =IFERROR((VLOOKUP(C12,PC!$A$1:$K$435,7,FALSE)&" "&VLOOKUP(C12,PC!$A$1:$K$435,6,FALSE)),"") -> 성주컴텍 SD100-GCR22S | E12: =IFERROR(VLOOKUP(C12,PC!$A$1:$K$435,2,FALSE),"") -> 20201102-0883 | G12: =$A$2&B12 -> 10.54.36.11
B13: 12 | C13: 생명과학실험실 교사용 | D13: =IFERROR((VLOOKUP(C13,PC!$A$1:$K$435,7,FALSE)&" "&VLOOKUP(C13,PC!$A$1:$K$435,6,FALSE)),"") -> 성주컴텍 SD100-GCR22S | E13: =IFERROR(VLOOKUP(C13,PC!$A$1:$K$435,2,FALSE),"") -> 20201102-0882 | G13: =$A$2&B13 -> 10.54.36.12
B14: 13 | C14: 화학실험실 교사용 | D14: =IFERROR((VLOOKUP(C14,PC!$A$1:$K$435,7,FALSE)&" "&VLOOKUP(C14,PC!$A$1:$K$435,6,FALSE)),"") -> 성주컴텍 SD100-GCR22S | E14: =IFERROR(VLOOKUP(C14,PC!$A$1:$K$435,2,FALSE),"") -> 20201102-0881 | G14: =$A$2&B14 -> 10.54.36.13
B15: 14 | C15: 물리실험실 교사용 | D15: =IFERROR((VLOOKUP(C15,PC!$A$1:$K$435,7,FALSE)&" "&VLOOKUP(C15,PC!$A$1:$K$435,6,FALSE)),"") -> 성주컴텍 SD100-GCR22S | E15: =IFERROR(VLOOKUP(C15,PC!$A$1:$K$435,2,FALSE),"") -> 20201102-0880 | G15: =$A$2&B15 -> 10.54.36.14
B16: 15 | C16: 정보과학실 학생용 1 | D16: =IFERROR((VLOOKUP(C16,PC!$A$1:$K$435,7,FALSE)&" "&VLOOKUP(C16,PC!$A$1:$K$435,6,FALSE)),"") -> 레드스톤 VITO RMS-565S | E16: =IFERROR(VLOOKUP(C16,PC!$A$1:$K$435,2,FALSE),"") -> 20190927-0795 | G16: =$A$2&B16 -> 10.54.36.15
B17: 16 | C17: 정보과학실 학생용 2 | D17: =IFERROR((VLOOKUP(C17,PC!$A$1:$K$435,7,FALSE)&" "&VLOOKUP(C17,PC!$A$1:$K$435,6,FALSE)),"") -> 레드스톤 VITO RMS-565S | E17: =IFERROR(VLOOKUP(C17,PC!$A$1:$K$435,2,FALSE),"") -> 20190927-0796 | G17: =$A$2&B17 -> 10.54.36.16
B18: 17 | C18: 정보과학실 학생용 3 | D18: =IFERROR((VLOOKUP(C18,PC!$A$1:$K$435,7,FALSE)&" "&VLOOKUP(C18,PC!$A$1:$K$435,6,FALSE)),"") -> 레드스톤 VITO RMS-565S | E18: =IFERROR(VLOOKUP(C18,PC!$A$1:$K$435,2,FALSE),"") -> 20190927-0797 | G18: =$A$2&B18 -> 10.54.36.17
B19: 18 | C19: 정보과학실 학생용 4 | D19: =IFERROR((VLOOKUP(C19,PC!$A$1:$K$435,7,FALSE)&" "&VLOOKUP(C19,PC!$A$1:$K$435,6,FALSE)),"") -> 삼보 DG375-GA31-0BPS | E19: =IFERROR(VLOOKUP(C19,PC!$A$1:$K$435,2,FALSE),"") -> 20220117-0896 | G19: =$A$2&B19 -> 10.54.36.18
B20: 19 | C20: 정보과학실 학생용 5 | D20: =IFERROR((VLOOKUP(C20,PC!$A$1:$K$435,7,FALSE)&" "&VLOOKUP(C20,PC!$A$1:$K$435,6,FALSE)),"") -> 삼보 DG375-GA31-0BPS | E20: =IFERROR(VLOOKUP(C20,PC!$A$1:$K$435,2,FALSE),"") -> 20220117-0897 | G20: =$A$2&B20 -> 10.54.36.19
B21: 20 | C21: 정보과학실 학생용 6 | D21: =IFERROR((VLOOKUP(C21,PC!$A$1:$K$435,7,FALSE)&" "&VLOOKUP(C21,PC!$A$1:$K$435,6,FALSE)),"") -> 삼보 DG375-GA31-0BPS | E21: =IFERROR(VLOOKUP(C21,PC!$A$1:$K$435,2,FALSE),"") -> 20220117-0898 | G21: =$A$2&B21 -> 10.54.36.20
B22: 21 | C22: 정보과학실 학생용 7 | D22: =IFERROR((VLOOKUP(C22,PC!$A$1:$K$435,7,FALSE)&" "&VLOOKUP(C22,PC!$A$1:$K$435,6,FALSE)),"") -> 삼보 DG375-GA31-0BPS | E22: =IFERROR(VLOOKUP(C22,PC!$A$1:$K$435,2,FALSE),"") -> 20220117-0899 | G22: =$A$2&B22 -> 10.54.36.21
B23: 22 | C23: 정보과학실 학생용 8 | D23: =IFERROR((VLOOKUP(C23,PC!$A$1:$K$435,7,FALSE)&" "&VLOOKUP(C23,PC!$A$1:$K$435,6,FALSE)),"") -> 삼보 DG375-GA31-0BPS | E23: =IFERROR(VLOOKUP(C23,PC!$A$1:$K$435,2,FALSE),"") -> 20220117-0900 | G23: =$A$2&B23 -> 10.54.36.22
B24: 23 | D24: =IFERROR((VLOOKUP(C24,PC!$A$1:$K$435,7,FALSE)&" "&VLOOKUP(C24,PC!$A$1:$K$435,6,FALSE)),"") | E24: =IFERROR(VLOOKUP(C24,PC!$A$1:$K$435,2,FALSE),"") | G24: =$A$2&B24 -> 10.54.36.23
B25: 24 | D25: =IFERROR((VLOOKUP(C25,PC!$A$1:$K$435,7,FALSE)&" "&VLOOKUP(C25,PC!$A$1:$K$435,6,FALSE)),"") | E25: =IFERROR(VLOOKUP(C25,PC!$A$1:$K$435,2,FALSE),"") | G25: =$A$2&B25 -> 10.54.36.24
B26: 25 | G26: =$A$2&B26 -> 10.54.36.25
B27: 26 | G27: =$A$2&B27 -> 10.54.36.26
B28: 27 | G28: =$A$2&B28 -> 10.54.36.27
B29: 28 | G29: =$A$2&B29 -> 10.54.36.28
B30: 29 | G30: =$A$2&B30 -> 10.54.36.29
B31: 30 | G31: =$A$2&B31 -> 10.54.36.30
B32: 31 | G32: =$A$2&B32 -> 10.54.36.31
B33: 32 | G33: =$A$2&B33 -> 10.54.36.32
B34: 33 | G34: =$A$2&B34 -> 10.54.36.33
B35: 34 | G35: =$A$2&B35 -> 10.54.36.34
B36: 35 | G36: =$A$2&B36 -> 10.54.36.35
B37: 36 | G37: =$A$2&B37 -> 10.54.36.36
... B51: 50 | G51: =$A$2&B51 -> 10.54.36.50
B52: 51 | C52: 검색용1 | D52: =IFERROR((VLOOKUP(C52,PC!$A$1:$K$435,7,FALSE)&" "&VLOOKUP(C52,PC!$A$1:$K$435,6,FALSE)),"") -> 레드스톤 VITO RMS-565S | E52: =IFERROR(VLOOKUP(C52,PC!$A$1:$K$435,2,FALSE),"") -> 20190927-0790 | F52: 도서실 | G52: =$A$2&B52 -> 10.54.36.51 | H52: 확인필요
B53: 52 | C53: 검색용2 | D53: =IFERROR((VLOOKUP(C53,PC!$A$1:$K$435,7,FALSE)&" "&VLOOKUP(C53,PC!$A$1:$K$435,6,FALSE)),"") -> 레드스톤 VITO RMS-565S | E53: =IFERROR(VLOOKUP(C53,PC!$A$1:$K$435,2,FALSE),"") -> 20190927-0791 | G53: =$A$2&B53 -> 10.54.36.52 | H53: 확인필요
...

Sheet 정보화기기 명부
A1: 성명 | B1: 부서
A2: 나정훈 | B2: 1학년부
A3: 오옥선 | B3: 1학년부
A4: 박채은 | B4: 1학년부
A5: 노병철 | B5: 1학년부
A6: 고민숙 | B6: 1학년부
A7: 황은선 | B7: 1학년부
A8: 윤선영 | B8: 1학년부
A9: 원영주 | B9: 1학년부
A10: 정현숙 | B10: 1학년부
A11: 원선일 | B11: 2층 교무실
A12: 황경환 | B12: 2층 교무실
... A134: 화학실험실 교사용 | B134: 화학실험실

Sheet 인창고 관련 사이트
B2: URL | C2: ID | D2: P/W
A3: MS 클라우드 학교 계정 관리 | B3: https://cloud.goe.go.kr/admin/ | C3: inchangh | D3: icgo2018#
A4: 인창고 G Suiet 관리 | B4: https://accounts.google.com | C4: admin | D4: dlsckdrh#2019
A5: 인창고 Domain 관리 | B5: https://my.inames.co.kr | C5: inchanghs | D5: dlsckdrh#2018
A6: 인창고 홈페이지 관리 | B6: http://211.184.232.146/inchang-h/main.do | C6: goegn159 | D6: goegn159#$ | E6: (2024년부터 변경)
A7: 교육청 교육정보기기 관리시스템 | B7: http://egms.ken.go.kr | C7: J100000769 | D7: icgo2018#
C8: 관리자 | D8: icgo2018#
A9: AhnLab EPP | B9: https://10.0.100.73:8806/ | C9: gn_ic_hs | D9: icgo20#24
A10: Privay-I 관리자 계정 목록 | B10: https://10.59.1.24/DLPCenter | C10: GN_HS_ICADMIN | D10: ic2018###
A11: Privay-I 관리자 계정 목록(구) | B11: http://218.234.92.181:8080/DLPCenter | C11: KN_HI_INC_ADMIN | D11: ic2018###
A12: plotter OneDrive 계정 | C12: plotter@inchangh.goe.go.kr | D12: icgo2018##
A13: iam Teacher | B13: https://teacher.iamservice.net/ | C13: 인창고등학교 | D13: icgo2018#
A14: 인창고 YouTube 용 계정 | C14: inchanggo@inchang.hs.kr | D14: ic2018###
A15: 방송반 인창고 계정 | C15: ibc@inchang.hs.kr | D15: 방송부1234!
A16: 방송반 어도비 계정 | C16: ibc@inchang.hs.kr | D16: 방송부1234!Q | E16: 생년월일 1996년 1월 13일 (인창고 개교일)
A17: 방송반 지니 계정 | C17: ibcinchang | D17: 방송부2018 | E17: 가입이메일: ibc@inchang.hs.kr
A18: 교사용 패들렛 계정 | C18: padlet@inchang.hs.kr | D18: ic2018###
A19: 무선통합관리시스템(wNMS) | B19: http://10.0.200.219:8080 | C19: G21_138 | D19: icgo2018#
A20: 스마트 단말 관리 시스템(MDM) | B20: https://mdm.aiedu.or.kr/ | C20: G21_138 | D20: icgo2018#
B21: https://mdm.goe.go.kr/onm/mas/main/main.html | C21: G21_138 | D21: smart21_138
A22: 경기도교육청 메신저 관리자 페이지 | B22: https://msg.goe.go.kr:18007/ | C22: H41001470 | D22: icgo2018#
A23: 클라우드서비스 통합로그인 지원시스템 | B23: https://www.goedu.kr/scmnst/login | E23: (관리자변경시 공문 발송)관련:교육정보화과-1846(2025.2.21.)
A24: GSMS시스템(단말기 a/s처리) | B24: https://gsms.goe.go.kr/
A26: 2024년12월 | E26: 경기도 상용클라우드
A27: 가입인증키 | B27: MVNIU-IGEVP-NSYAW-XFHQI | E27: 교직원가입키 : MVNIU-IGEVP-NSYAW-XFHQI
E28: 학생가입키 : MSGOO-SFHWA-GOOXX-OLIKN

Sheet 프린터 IP
B1: IP | C1: 부서 | D1: 종류 | E1: 모델명 | F1: 프린터 관리자 | H1: 물품번호 | I1: 구입일자
A2: 대역폭 | F2: ID | G2: P/W
A3: 10.51.90. | B3: 18 | E3: CCTV 1
B4: 19 | E4: CCTV 2
B5: 20 | E5: CCTV 3
B6: 21
B7: 22 | E7: ASUSTek COMPUTER INC.
B8: 23 | C8: 교무기획부 | D8: 복사기 | E8: Kyocera TASKalfa 3510i | F8: Admin | G8: Admin | H8: 44101501-22674348 | I8: 2016.02.26
B9: 24 | C9: 행정실 | D9: 프린터 | E9: Kyocera ECOSYS P7040cdn | H9: 43212105-23060005 | I9: 2019.03.05
B10: 25 | C10: 행정실 | D10: 프린터 | E10: Kyocera ECOSYS M5526cdn | F10: Admin | G10: Admin
B11: 26 | C11: 행정실 | D11: 프린터 | E11: Kyocera FS-4100DN | H11: 43212105-22449325 | I11: 2015.06.24
B12: 27 | C12: 교무기획부 | D12: 복사기 | E12: Document Centre C250
B13: 28 | C13: 시설관리실 | D13: 프린터 | E13: Kyocera P2235dnG | F13: Admin | G13: Admin | I13: 2019.11. 10
B14: 29
B15: 30
B16: 31 | C16: 행정실무사 | D16: 프린터 | E16: Brother HL-L5100DN | H16: 43212105-22999063 | I16: 2017.03.30
B17: 32 | C17: 체육보건부 | D17: 복사기 | E17: DocuCentre-II 2055
B18: 33
B19: 34 | C19: 체육보건부 | D19: 프린터 | E19: Kyocera ECOSYS M5526cdn | F19: Admin | G19: Admin
B20: 35 | C20: 교육정보부 | D20: 복사기 | E20: Canon imageRUNNER 2204F | F20: 7654321 | G20: 7654321 | I20: 2017.04.01
B21: 36 | C21: 교육정보부 | D21: 플로터 | E21: HP Designjet Z5200 PostScript | H21: 43212107-22449586 | I21: 2016.02.04
B22: 37 | C22: 학생부 | D22: 프린터 | E22: TASKalfa 4012i | F22: Admin | G22: Admin
B23: 38 | C23: 학생부 | D23: 프린터 | E23: HL-L8260CDN | I23: 2025.3.27
B24: 39
B25: 40 | C25: 교육정보부 | D25: 프린터 | E25: HP DesignJet Z6 24in
B26: 41 | C26: 도서실 | D26: 프린터 | E26: Canon, (VN)GX6091 | I26: 20240524
B27: 42
B28: 43 | C28: 도서실 | D28: 복사기 | E28: ﻿SINDOH ﻿N606 42BW-4 (Generic) | H28: 44101501-22032177 | I28: 2012.08.23
B29: 44 | C29: 인문사회부 | D29: 프린터 | E29: TASKalfa3554ci | I29: 2024.04.12
B30: 45 | C30: 인문사회부 | D30: 프린터 | E30: Kyocera TASKalfa 3011i | F30: Admin | G30: Admin | H30: 44101501-23212449 | I30: 2017.12.18
B31: 46 | C31: 과학부 | D31: 프린터 | E31: EPSON B-310N | H31: 43212104-21788706 | I31: 2014.06.02
B32: 47 | C32: 수리과학부 | D32: 프린터 | E32: Kyocera ECOSYS P6235cdn | F32: Admin | G32: Admin | H32: 43212105-23428140 | I32: 20220225 | J32: 확인완료
B33: 48 | C33: 수리과학부 | D33: 복사기 | E33: Kyocera TASKalfa 3253ci | H33: 44101501-23579683 | I33: 20210127 | J33: 확인완료
B34: 49 | C34: 진로상담 | D34: 프린터 | E34: DocuPrint C2200 | H34: 43212105-21525144 | I34: 2010.11.11
B35: 50
B36: 51 | C36: 진로상담 | D36: 복사기 | E36: DocuCentre-II 3005G | H36: 44101503-21171456 | I36: 2008.07.25
B37: 52 | C37: 수업나눔터
B38: 53
B39: 54 | C39: 4층 미술실 | D39: 프린터 | E39: EPSON WF-5620 | H39: 44101503-22880368 | I39: 2017.10.21
B40: 55 | C40: 통합교육지원실 | D40: 복합기 | E40: TASKalfa2554ciG | H40: 마라톤 상사 임대 | I40: 2025.3.
...

Sheet AP현황
A1: AP 명 | B1: AP Mac | C1: AP IP | D1: AP 번호 | E1: 설치 층 | F1: 설치 장소
A2: Gyeonggi_inchang.hs_AP01 | B2: 1C:EC:72:01:57:F3 | C2: 10.59.87.147 | D2: 97343 | E2: 1층 | F2: 통합교육지원실2
A3: Gyeonggi_inchang.hs_AP02 | B3: 1C:EC:72:01:57:F8 | C3: 10.59.87.148 | D3: 97344 | E3: 1층 | F3: 통합교육지원실1
A4: Gyeonggi_inchang.hs_AP03 | B4: 1C:EC:72:01:57:FD | C4: 10.59.87.149 | D4: 97345 | E4: 2층 | F4: 교과교실(수학)
A5: Gyeonggi_inchang.hs_AP04 | B5: 1C:EC:72:01:58:02 | C5: 10.59.87.150 | D5: 97346 | E5: 2층 | F5: 1-1
A6: Gyeonggi_inchang.hs_AP05 | B6: 1C:EC:72:01:58:07 | C6: 10.59.87.151 | D6: 97347 | E6: 2층 | F6: 1-2
A7: Gyeonggi_inchang.hs_AP06 | B7: 1C:EC:72:01:58:0C | C7: 10.59.87.152 | D7: 97348 | E7: 2층 | F7: 1-3
A8: Gyeonggi_inchang.hs_AP07 | B8: 1C:EC:72:01:58:11 | C8: 10.59.87.153 | D8: 97349 | E8: 4층 | F8: 3-9 | G8: 예전3층2-9
A9: Gyeonggi_inchang.hs_AP08 | B9: 1C:EC:72:01:58:16 | C9: 10.59.87.154 | D9: 97350 | E9: 3층 | F9: 2-8
A10: Gyeonggi_inchang.hs_AP09 | B10: 1C:EC:72:01:58:1B | C10: 10.59.87.155 | D10: 97351 | E10: 3층 | F10: 2-7
A11: Gyeonggi_inchang.hs_AP10 | B11: 1C:EC:72:01:58:20 | C11: 10.59.87.156 | D11: 97352 | E11: 3층 | F11: 2-6
A12: Gyeonggi_inchang.hs_AP11 | B12: 1C:EC:72:01:58:25 | C12: 10.59.87.157 | D12: 97353 | E12: 3층 | F12: White spac
A13: Gyeonggi_inchang.hs_AP12 | B13: 1C:EC:72:01:58:2A | C13: 10.59.87.158 | D13: 97354 | E13: 5층 | F13: 오디움실 | G13: 예전3층미술실2
A14: Gyeonggi_inchang.hs_AP13 | B14: 1C:EC:72:01:58:2F | C14: 10.59.87.159 | D14: 97355 | E14: 3층 | F14: 1-4
A15: Gyeonggi_inchang.hs_AP14 | B15: 1C:EC:72:01:58:34 | C15: 10.59.87.160 | D15: 97356 | E15: 3층 | F15: 1-5
A16: Gyeonggi_inchang.hs_AP15 | B16: 1C:EC:72:01:58:39 | C16: 10.59.87.161 | D16: 97357 | E16: 3층 | F16: 1-6
A17: Gyeonggi_inchang.hs_AP16 | B17: 1C:EC:72:01:58:3E | C17: 10.59.87.162 | D17: 97358 | E17: 3층 | F17: 1-7
A18: Gyeonggi_inchang.hs_AP17 | B18: 1C:EC:72:01:58:43 | C18: 10.59.87.163 | D18: 97359 | E18: 3층 | F18: 1-8
A19: Gyeonggi_inchang.hs_AP18 | B19: 1C:EC:72:01:58:48 | C19: 10.59.87.164 | D19: 97360 | E19: 4층 | F19: 2-1
A20: Gyeonggi_inchang.hs_AP19 | B20: 1C:EC:72:01:58:4D | C20: 10.59.87.165 | D20: 97361 | E20: 4층 | F20: 2-2
A21: Gyeonggi_inchang.hs_AP20 | B21: 1C:EC:72:01:58:52 | C21: 10.59.87.166 | D21: 97362 | E21: 4층 | F21: 2-3
A22: Gyeonggi_inchang.hs_AP21 | B22: 1C:EC:72:01:58:57 | C22: 10.59.87.167 | D22: 97363 | E22: 4층 | F22: 2-4
A23: Gyeonggi_inchang.hs_AP22 | B23: 1C:EC:72:01:58:5C | C23: 10.59.87.168 | D23: 97364 | E23: 4층 | F23: 2-5
A24: Gyeonggi_inchang.hs_AP23 | B24: 1C:EC:72:01:58:61 | C24: 10.59.87.169 | D24: 97365 | E24: 4층 | F24: 3-7
A25: Gyeonggi_inchang.hs_AP24 | B25: 1C:EC:72:01:58:66 | C25: 10.59.87.170 | D25: 97366 | E25: 4층 | F25: 3-8
... A34: Gyeonggi_inchang.hs_AP33 | B34: 1C:EC:72:01:58:93 | C34: 10.59.87.179 | D34: 97375 | E34: 4층 | F34: 음악실
E35: 5층 | F35: 오디움실 | G35: 예전5층학생통합지원실1 | I35: 확인필요

Sheet 전자칠판
A1: < 전자칠판 위치 >(총 11대)
A3: 1층 | B3: 도서관 | C3: 1대
A4: 2층 | B4: 수학교과실 | C4: 1대
B5: 생물실 | C5: 1대
B6: 화학실 | C6: 1대
B7: 컴퓨터실2 | C7: 1대
A8: 3층 | B8: 정보과학실 | C8: 1대
B9: 지구과학실 | C9: 1대
B10: 물리실 | C10: 1대
A11: 4층 | B11: 중국어교과실 | C11: 1대
A12: 5층 | B12: 오디움실 | C12: 2대

Sheet 교실충전함
A1: 학년반 | B1: 제품명 | C1: 관리번호 | D1: 큐알코드 여부
A2: 1학년1반 | B2: 스마트아이디어, SCB-40R | C2: 3-2-07-3-1-025-7-0006 | D2: O
A3: 1학년2반 | B3: 스마트아이디어, SCB-40R | C3: 3-2-07-3-1-025-7-0005 | D3: O
A4: 1학년3반 | B4: 스마트아이디어, SCB-40R | C4: 3-2-07-3-1-025-7-0007 | D4: O
A5: 1학년4반 | B5: 스마트아이디어, SCB-40R | C5: 3-2-07-3-1-025-7-0011 | D5: O
A6: 1학년5반 | B6: 스마트아이디어, SCB-40R | C6: 3-2-07-3-1-025-7-0009 | D6: O
A7: 1학년6반 | B7: 스마트아이디어, SCB-40R | C7: 3-2-07-3-1-025-7-0012 | D7: O
A8: 1학년7반 | B8: 스마트아이디어, SCB-40R | C8: 3-2-07-3-1-025-7-0008 | D8: O
A9: 1학년8반 | B9: 스마트아이디어, SCB-40R | C9: 3-2-07-3-1-025-7-0010 | D9: O
A10: 2학년1반 | B10: 도원산업, CF1-BTL33 | C10: 3-2-07-3-1-025-7-0017 | D10: O
A11: 2학년2반 | B11: 도원산업, CF1-BTL33 | C11: 3-2-07-3-1-025-7-0016 | D11: O
A12: 2학년3반 | B12: 스마트엑세스, D-30FWH | C12: 3-2-07-3-1-025-7-0004 | D12: O
... A17: 2학년8반 | B17: 스마트엑세스, D-30FWH | C17: 3-2-07-3-1-025-7-0003 | D17: O
A18: 3학년1반 | B18: 도원산업, CF1-BTL30S1 | D18: X
A19: 3학년2반 | B19: 도원산업, CF1-BTL30S1 | D19: X
A20: 3학년3반 | B20: 도원산업, CF1-BTL30S1 | D20: X
A21: 3학년4반 | B21: 도원산업, CF1-BTL30S1 | D21: X
A22: 3학년5반 | B22: 도원산업, CF1-BTL30S1 | D22: X
A23: 3학년6반 | B23: 도원산업, CF1-BTL30S1 | D23: X
A24: 3학년7반 | B24: 도원산업, CF1-BTL30S1 | D24: X
A25: 3학년8반 | B25: 도원산업, CF1-BTL30S1 | D25: X
A26: 3학년9반 | B26: 도원산업, CF1-BTL33 | C26: 3-2-07-3-1-025-7-0015 | D26: O

Sheet Sheet2
A1: Kyocera TASKalfa 3010i 토너 | G1: Kyocera TASKalfa 4002i (1, 3학년부) | M1: Kyocera TASKalfa 3011i
A2: 1학년부 | G2: Kyocera TASKalfa 5003i (1, 2학년부) | M2: 인문사회부
A3: TK-7109(3010i) | G3: TK-6329K | M3: TK-7119K(3011i)
A4: 구입 | C4: 소모 | F4: 잔고 | G4: 구입 | I4: 소모 | L4: 잔고 | M4: 구입 | O4: 소모 | R4: 잔고
A5: 구입일자 | B5: 개수 | C5: 소모일자 | D5: 부서 | E5: 개수 | F5: 잔고 | G5: 구입일자 | H5: 개수 | I5: 소모일자 | J5: 부서 | K5: 개수 | L5: 잔고 | M5: 구입일자 | N5: 개수 | O5: 소모일자 | P5: 부서 | Q5: 개수 | R5: 잔고
A6: 43454 | B6: 7 | F6: 7 | G6: 43525 | H6: 5 | L6: =H6 -> 5 | M6: 43525 | N6: 2 | R6: 2
C7: 43475 | D7: 1학년부 | E7: 1 | F7: =F6+B7-E7 -> 6 | I7: 43537 | J7: 3학년부 | K7: 1 | L7: =L6+H7-K7 -> 4 | O7: 43571 | P7: 인사부 | Q7: 1 | R7: =R6+N7-Q7 -> 1
C8: 43516 | D8: 2학년부 | E8: 1 | F8: =F7+B8-E8 -> 5 | G8: 43677 | H8: 1 | L8: =L7+H8-K8 -> 5 | O8: 43636 | P8: 인사부 | Q8: 1 | R8: =R7+N8-Q8 -> 0
C9: ? | D9: ? | E9: 1 | F9: =F8+B9-E9 -> 4 | I9: 43621 | J9: 3학년부 | K9: 2 | L9: =L8+H9-K9 -> 3 | M9: 2019-10-11(재생) | N9: 1 | O9: 43749 | P9: 인사부 | Q9: 1 | R9: =R8+N9-Q9 -> 0
C10: 43607 | D10: 1학년부 | E10: 1 | F10: =F9+B10-E10 -> 3 | I10: 43677 | J10: 3학년부 | K10: 1 | L10: =L9+H10-K10 -> 2 | M10: 2019.12.05(마라톤) | N10: 4 | R10: =R9+N10-Q10 -> 4
C11: 43671 | D11: 2학년부 | E11: 1 | F11: =F10+B11-E11 -> 2 | I11: 43776 | J11: 3학년부 | K11: 1 | L11: =L10+H11-K11 -> 1 | O11: 43922 | P11: 인사부 | Q11: 1 | R11: =R10+N11-Q11 -> 3
C12: 43749 | D12: 1학년부 | E12: 1 | F12: =F11+B12-E12 -> 1 | G12: 2020-02-04(마라톤) | H12: 5 | L12: =L11+H12-K12 -> 6 | O12: 44061 | P12: 인사부 | Q12: 1 | R12: =R11+N12-Q12 -> 2
A13: 43849 | B13: 1 | F13: =F12+B13-E13 -> 2 | I13: 44010 | J13: 3학년부 | K13: 1 | L13: =L12+H13-K13 -> 5 | O13: 44228 | P13: 2학년부 | Q13: 1 | R13: =R12+N13-Q13 -> 1
A14: 43874 | B14: 7 | F14: =F13+B14-E14 -> 9 | I14: 44061 | J14: 3학년부 | K14: 1 | L14: =L13+H14-K14 -> 4 | O14: 44249 | P14: 인사부 | Q14: 1 | R14: =R13+N14-Q14 -> 0
C15: 43755 | D15: 2학년부 | E15: 1 | F15: =F14+B15-E15 -> 8 | I15: 44083 | J15: 1학년부 | K15: 1 | L15: =L14+H15-K15 -> 3 | M15: 2021-02-23(마라톤) | N15: 2 | R15: =R14+N15-Q15 -> 2
C16: 43849 | D16: 2학년부 | E16: 1 | F16: =F15+B16-E16 -> 7 | I16: 44097 | J16: 3학년부 | K16: 1 | L16: =L15+H16-K16 -> 2 | O16: 44349 | P16: 인사부 | Q16: 1 | R16: =R15+N16-Q16 -> 1
C17: 44018 | D17: 2학년부 | E17: 1 | F17: =F16+B17-E17 -> 6 | G17: 2021-02-23(마라톤) | H17: 5 | L17: =L16+H17-K17 -> 7 | O17: 44474 | P17: 인사부 | Q17: 1 | R17: =R16+N17-Q17 -> 0
A18: 43901 | B18: 7 | F18: =F17+B18-E18 -> 13 | I18: 44267 | J18: 3학년부 | K18: 1 | L18: =L17+H18-K18 -> 6 | M18: 2021-10-06(교환) | N18: 1 | R18: =R17+N18-Q18 -> 1
C19: 44088 | D19: 1학년부 | E19: 1 | F19: =F18+B19-E19 -> 12 | I19: 43905 | J19: 1학년부 | K19: 1 | L19: =L18+H19-K19 -> 5 | M19: 2022-03-07(누락분) | N19: 2 | R19: =R18+N19-Q19 -> 3
C20: 44146 | D20: 2학년부 | E20: 1 | F20: =F19+B20-E20 -> 11 | G20: 2021-05-28(마라톤 교환) | H20: 5 | L20: =L19+H20-K20 -> 10 | O20: 44627 | P20: 인사부 | Q20: 1 | R20: =R19+N20-Q20 -> 2
C21: 44202 | D21: 2학년부 | E21: 1 | F21: =F20+B21-E21 -> 10 | I21: 44350 | J21: 3학년부 | K21: 1 | L21: =L20+H21-K21 -> 9 | M21: 2022-03-23(교환) | N21: 1 | R21: =R20+N21-Q21 -> 3
C22: 44326 | D22: 2학년부 | E22: 1 | F22: =F21+B22-E22 -> 9 | I22: 44431 | J22: 3학년부 | K22: 1 | L22: =L21+H22-K22 -> 8 | O22: 44715 | P22: 인사부 | Q22: 1 | R22: 2
C23: 44344 | D23: 마라톤 교환 | E23: 7 | F23: =F22+B23-E23 -> 2 | I23: 44446 | J23: 1학년부 | K23: 1 | L23: =L22+H23-K23 -> 7 | O23: 44838 | P23: 인사부 | Q23: 1 | R23: 1
C24: 44475 | D24: 마라톤 교환 | E24: 1 | F24: =F23+B24-E24 -> 1 | I24: 44475 | J24: 3학년부 | K24: 1 | L24: =L23+H24-K24 -> 6
C25: 44643 | D25: 마라톤 교환 | E25: 1 | F25: 0 | G25: 2022-03-07(누락분) | H25: 5 | L25: =L24+H25-K25 -> 11
A26: 사 | B26: 용 | C26: 종 | D26: 료 | I26: 44523 | J26: 2학년부 | K26: 1 | L26: =L25+H26-K26 -> 10
I27: 44627 | J27: 3학년부 | K27: 1 | L27: =L26+H27-K27 -> 9
I28: 44651 | J28: 2학년부 | K28: 1 | L28: =L27+H28-K28 -> 8
I29: ? | J29: ? | K29: 1 | L29: 7
I30: 44736 | J30: 3학년부 | K30: 1 | L30: 6
I31: 44736 | J31: 2학년부 | K31: 1 | L31: 5
I32: 44753 | J32: 1학년부 | K32: 1 | L32: 4
I33: 44792 | J33: 3학년부 | K33: 1 | L33: 3
I34: 44832 | J34: 1학년부 | K34: 1 | L34: 2
I35: 44834 | J35: 3학년부 | K35: 1 | L35: 1
I36: 44839 | J36: 2학년부 | K36: 1 | L36: 0
G37: 2022-10-05(마라톤) | H37: 6
M42: 마라톤 | O42: 556-5211~2
A46: DocuPrint 3055 | G46: Sindoh B601_606 | M46: SINDOH ﻿N607 42BW-4 | S46: Kyocera FS-4100DN | Y46: Kyocera FS-6975DN
A47: 체육보건부 | G47: 체육보건부 | M47: 도서실 | S47: 2, 3학년부 | Y47: 3학년부(부장)
...

Sheet Sheet1
A1: 물품목록번호 | B1: 물품분류명 | C1: 품명/규격 | D1: 취득일 | E1: 취득구분 | F1: 운용부서 | G1: 수량 | H1: 단가 | I1: 취득금액 | J1: 내용연수
A2: 44101501-20752268 | B2: 복사기 | C2: 신도리코, Aficio 2127 | D2: 2007.06.25 | E2: 조달구입 | F2: 1학년교무실 | G2: 1 | H2: 2794000 | I2: 2794000 | J2: 4
A3: 44101503-20426960 | B3: 다기능복사기 | C3: (옵션)신도리코, 자동원고송고장치, ADF | D3: 2007.06.25 | E3: 분류전환+ | F3: 1학년교무실 | G3: 1 | H3: 836000 | I3: 836000 | J3: 5
A4: 44101503-20427050 | B4: 다기능복사기 | C4: (옵션)청호컴넷, Network printer kit, CHC-360G용 | D4: 2007.06.25 | E4: 분류전환+ | F4: 1학년교무실 | G4: 1 | H4: 836000 | I4: 836000 | J4: 5
A5: 43212105-21084845 | B5: 레이저프린터 | C5: 한국후지제록스, CN/DocuPrint 2065, 26ppm | D5: 2010.05.13 | E5: 조달구입 | F5: 1학년교무실 | G5: 1 | H5: 657680 | I5: 657680 | J5: 5
A6: 43212105-21525085 | B6: 레이저프린터 | C6: 한국후지제록스, CN/DocuPrint 3055K, A3/흑백, 35ppm, 급지장치 550매 Tray 기본형 | D6: 2011.07.12 | E6: 조달구입 | F6: 1학년교무실 | G6: 1 | H6: 1105340 | I6: 1105340 | J6: 5 | K6: 구 3학년교무실
A7: 44101501-22674347 | B7: 복사기 | C7: Kyocera document solutios, CN/TASKalfa3010iG, 흑백30cpm | D7: 2015.03.26 | E7: 조달구입 | F7: 1학년교무실 | G7: 1 | H7: 2490970 | I7: 2490970 | J7: 5
A8: 43212105-20704676 | B8: 레이저프린터 | C8: 정원엔시스템, Hart-2612MW | D8: 2001.01.01 | E8: 자체구입 | F8: 2층교무실 | G8: 1 | H8: 660000 | I8: 660000 | J8: 5
A9: 43212105-20704676 | B9: 레이저프린터 | C9: 정원엔시스템, Hart-2612MW | D9: 2001.05.04 | E9: 조달구입 | F9: 2층교무실 | G9: 1 | H9: 704000 | I9: 704000 | J9: 5
A10: 43212105-20704676 | B10: 레이저프린터 | C10: 정원엔시스템, Hart-2612MW | D10: 2001.05.19 | E10: 조달구입 | F10: 2층교무실 | G10: 1 | H10: 704000 | I10: 704000 | J10: 5
A11: 43212105-20704676 | B11: 레이저프린터 | C11: 정원엔시스템, Hart-2612MW | D11: 2002.03.25 | E11: 자체구입 | F11: 2층교무실 | G11: 1 | H11: 499000 | I11: 499000 | J11: 5
A12: 43212105-20704676 | B12: 레이저프린터 | C12: 정원엔시스템, Hart-2612MW | D12: 2004.09.16 | E12: 조달구입 | F12: 2층교무실 | G12: 2 | H12: 1464720 | I12: 2929440 | J12: 5
A13: 43212105-20505550 | B13: 레이저프린터 | C13: 한국후지제록스, DocuPrint 255, A3, 25ppm | D13: 2006.05.08 | E13: 조달구입 | F13: 2층교무실 | G13: 1 | H13: 915200 | I13: 915200 | J13: 5
A14: 43212105-20523512 | B14: 레이저프린터 | C14: 한국후지제록스, DocuPrint 305, A3/흑백, 30ppm | D14: 2010.03.06 | E14: 조달구입 | F14: 2층교무실 | G14: 1 | H14: 817300 | I14: 817300 | J14: 5
A15: 43212105-21525144 | B15: 레이저프린터 | C15: 한국후지제록스, CN/DocuPrint C 2200, A4/컬러, 25ppm | D15: 2010.05.06 | E15: 조달구입 | F15: 2층교무실 | G15: 2 | H15: 663205 | I15: 1326410 | J15: 5 | K15: 교감
A16: 43212105-22999063 | B16: 레이저프린터 | C16: Brother, VN/HL-L5100DN, A4/흑백/40ppm | D16: 2017.03.30 | E16: 조달구입 | F16: 2층교무실 | G16: 1 | H16: 442370 | I16: 442370 | J16: 6 | K16: 행정실무사
A17: 43212105-20704676 | B17: 레이저프린터 | C17: 정원엔시스템, Hart-2612MW | D17: 2002.03.25 | E17: 자체구입 | F17: 2학년교무실 | G17: 1 | H17: 499000 | I17: 499000 | J17: 5
A18: 43212105-20523512 | B18: 레이저프린터 | C18: 한국후지제록스, DocuPrint 305, A3/흑백, 30ppm | D18: 2006.05.08 | E18: 조달구입 | F18: 2학년교무실 | G18: 1 | H18: 1193500 | I18: 1193500 | J18: 5
A19: 44101503-21171456 | B19: 다기능복사기 | C19: 한국후지제록스, CN/DCII 3005, 복사기능기본+네트웍프린터KIT+RADF/자동원고이송장치추가장착, 흑백 | D19: 2008.07.25 | E19: 자체구입 | F19: 2학년교무실 | G19: 1 | H19: 4667400 | I19: 4667400 | J19: 5
A20: 43212105-22449325 | B20: 레이저프린터 | C20: Kyocera document solutions, CN/FS-4100DNG, 흑백/45ppm | D20: 2014.01.20 | E20: 조달구입 | F20: 2학년교무실 | G20: 1 | H20: 631780 | I20: 631780 | J20: 5
A21: 44101501-22674347 | B21: 복사기 | C21: Kyocera document solutios, CN/TASKalfa3010iG, 흑백30cpm | D21: 2016.08.24 | E21: 조달구입 | F21: 2학년교무실 | G21: 1 | H21: 2490970 | I21: 2490970 | J21: 6
A22: 43212105-20704676 | B22: 레이저프린터 | C22: 정원엔시스템, Hart-2612MW | D22: 2002.06.22 | E22: 조달구입 | F22: 3학년교무실 | G22: 2 | H22: 568700 | I22: 1137400 | J22: 5
A23: 43212105-20704694 | B23: 레이저프린터 | C23: Kodak, JP/Kodak XLS 8600 Color Printer, A4 | D23: 2002.06.22 | E23: 조달구입 | F23: 3학년교무실 | G23: 2 | H23: 295900 | I23: 591800 | J23: 5
A24: 43212105-20704676 | B24: 레이저프린터 | C24: 정원엔시스템, Hart-2612MW | D24: 2003.10.16 | E24: 자체구입 | F24: 3학년교무실 | G24: 1 | H24: 1090430 | I24: 1090430 | J24: 5
A25: 43212105-20704676 | B25: 레이저프린터 | C25: 정원엔시스템, Hart-2612MW | D25: 2005.03.11 | E25: 조달구입 | F25: 3학년교무실 | G25: 2 | H25: 962500 | I25: 1925000 | J25: 5
A26: 44101501-20838515 | B26: 복사기 | C26: 한국후지제록스, DCIIC 3000G, 디지털(흑백/컬러겸용) | D26: 2008.02.05 | E26: 자체구입 | F26: 3학년교무실 | G26: 1 | H26: 2820000 | I26: 2820000 | J26: 4
A27: 44101503-20427057 | B27: 다기능복사기 | C27: (옵션)한국후지제록스, Network printer kit, DCC320/400용 | D27: 2008.02.05 | E27: 분류전환+ | F27: 3학년교무실 | G27: 1 | H27: 757000 | I27: 757000 | J27: 5
A28: 44101503-20427087 | B28: 다기능복사기 | C28: (옵션)한국후지제록스, ADF, 자동원고송고장치 | D28: 2008.02.05 | E28: 분류전환+ | F28: 3학년교무실 | G28: 1 | H28: 757000 | I28: 757000 | J28: 5
A29: 44101501-22032178 | B29: 복사기 | C29: 신도리코, N607, 모노 42매, 컬러스캔가능 | D29: 2012.08.23 | E29: 조달구입 | F29: 3학년교무실 | G29: 1 | H29: 4125150 | I29: 4125150 | J29: 5 | K29: 구행정실
A30: 43212105-21727786 | B30: 레이저프린터 | C30: Kyoceramita, CN/FS-6975DNG, A3/흑백 35ppm | D30: 2014.01.20 | E30: 조달구입 | F30: 3학년교무실 | G30: 1 | H30: 775500 | I30: 775500 | J30: 5
A31: 43212105-22449325 | B31: 레이저프린터 | C31: Kyocera document solutions, CN/FS-4100DNG, 흑백/45ppm | D31: 2014.01.20 | E31: 조달구입 | F31: 3학년교무실 | G31: 1 | H31: 631780 | I31: 631780 | J31: 5
A32: 44101501-20498947 | B32: 복사기 | C32: 신도리코, Aficio 2032, 디지털복합기겸용, 흑백 | D32: 2005.03.10 | E32: 조달구입 | F32: 3학년상담실 | G32: 1 | H32: 4235000 | I32: 4235000 | J32: 5
A33: 43212105-20704676 | B33: 레이저프린터 | C33: 정원엔시스템, Hart-2612MW | D33: 2005.04.06 | E33: 조달구입 | F33: 가사실 | G33: 1 | H33: 660000 | I33: 660000 | J33: 5
A34: 43212104-21112991 | B34: 잉크젯프린터 | C34: 잉크젯프린터, 한국HP, K5400DN, A4/컬러, 35/36ppm | D34: 2009.12.21 | E34: 조달구입 | F34: 과학과 | G34: 1 | H34: 400000 | I34: 400000 | J34: 5
A35: 43212105-21084844 | B35: 레이저프린터 | C35: 한국후지제록스, CN/DocuPrint 3055, A3/흑백, 35ppm | D35: 2009.12.21 | E35: 조달구입 | F35: 과학과 | G35: 1 | H35: 780000 | I35: 780000 | J35: 5
A36: 44101501-22032177 | B36: 복사기 | C36: 신도리코, N606, 모노 36매, 컬러스캔가능 | D36: 2013.03.07 | E36: 조달구입 | F36: 과학과 | G36: 1 | H36: 3099360 | I36: 3099360 | J36: 5
A37: 43212104-21788706 | B37: 잉크젯프린터 | C37: 잉크젯프린터, Epson, JP/B-310N, A4 37ppm | D37: 2014.06.02 | E37: 자체구입 | F37: 과학과 | G37: 1 | H37: 261400 | I37: 261400 | J37: 5
A38: 43212105-20523596 | B38: 레이저프린터 | C38: 한국후지제록스, DPC2428, A3/컬러, 24/24ppm | D38: 2003.09.08 | E38: 자체구입 | F38: 과학실 | G38: 1 | H38: 303930 | I38: 303930 | J38: 5
A39: 43212105-20704676 | B39: 레이저프린터 | C39: 정원엔시스템, Hart-2612MW | D39: 2003.09.08 | E39: 조달구입 | F39: 과학실 | G39: 1 | H39: 786500 | I39: 786500 | J39: 5
A40: 43212105-20704676 | B40: 레이저프린터 | C40: 정원엔시스템, Hart-2612MW | D40: 2005.05.12 | E40: 조달구입 | F40: 과학실 | G40: 1 | H40: 3920400 | I40: 3920400 | J40: 5
...
